Workbook

Sheet Golf Scores
A1: Golfer | B1: Date | C1: Score | D1: Over Par | E1: Played With | F1: Par | G1: Course | H1: Tees | I1: Yardage | J1: Front 9 | K1: Back 9 | L1: Eagles | M1: Birdies | N1: Pars | O1: Bogeys | P1: Double Bogeys | Q1: Holes Played | R1: Putts | S1: Fairways | T1: Greens
A2: Tyler | B2: 45941 | C2: 91 | D2: 19 | E2: Dad | F2: =C2-D2 -> 72 | G2: Wind Watch Hamlet Course | H2: White | I2: 6030 | J2: 46 | K2: 45 | L2: 0 | M2: 1 | N2: 2 | O2: 9 | P2: 6 | Q2: =SUM(L2:P2) -> 18 | R2: 30 | S2: 3 | T2: 1
A3: Rich | B3: 45941 | C3: 91 | D3: 19 | E3: Tyler | F3: =C3-D3 -> 72 | G3: Wind Watch Hamlet Course | H3: White | I3: 6030 | J3: 46 | K3: 45 | L3: 0 | M3: 0 | N3: 3 | O3: 10 | P3: 5 | Q3: =SUM(L3:P3) -> 18 | R3: 33 | S3: 7 | T3: 1
A4: Tyler | B4: 45897 | C4: 89 | D4: 17 | E4: Rich | F4: =C4-D4 -> 72 | G4: Spring Lake Thunderbird | H4: Blue | I4: 6504 | J4: 44 | K4: 45 | L4: 0 | M4: 0 | N4: 5 | O4: 9 | P4: 4 | Q4: =SUM(L4:P4) -> 18 | R4: 31 | S4: 3 | T4: 4
A5: Rich | B5: 45897 | C5: 90 | D5: 18 | E5: Tyler | F5: =C5-D5 -> 72 | G5: Spring Lake Thunderbird | H5: Blue | I5: 6504 | J5: 43 | K5: 47 | L5: 0 | M5: 0 | N5: 3 | O5: 12 | P5: 3 | Q5: =SUM(L5:P5) -> 18 | R5: 32 | S5: 5 | T5: 0
A6: Tyler | B6: 45894 | C6: 95 | D6: 24 | E6: Ryan | F6: =C6-D6 -> 71 | G6: Willow Creek Hamlet Course | H6: Blue | I6: 6311 | J6: 45 | K6: 40 | L6: 0 | M6: 0 | N6: 2 | O6: 8 | P6: 8 | Q6: =SUM(L6:P6) -> 18 | R6: 38 | S6: 6 | T6: 1
A7: Ryan | B7: 45894 | C7: 112 | D7: 41 | E7: Tyler | F7: =C7-D7 -> 71 | G7: Willow Creek Hamlet Course | H7: Blue | I7: 6311 | J7: 58 | K7: 54 | L7: 0 | M7: 0 | N7: 0 | O7: 6 | P7: 12 | Q7: =SUM(L7:P7) -> 18 | R7: 42 | S7: 3 | T7: 3
A8: Tyler | B8: 45892 | C8: 85 | D8: 13 | E8: Rich | F8: =C8-D8 -> 72 | G8: Spring Lake Thunderbird | H8: Blue | I8: 6504 | J8: 45 | K8: 40 | L8: 0 | M8: 0 | N8: 7 | O8: 9 | P8: 2 | Q8: =SUM(L8:P8) -> 18 | R8: 32 | S8: 6 | T8: 5
A9: Rich | B9: 45892 | C9: 90 | D9: 18 | E9: Tyler | F9: =C9-D9 -> 72 | G9: Spring Lake Thunderbird | H9: Blue | I9: 6504 | J9: 44 | K9: 46 | L9: 0 | M9: 0 | N9: 6 | O9: 7 | P9: 5 | Q9: =SUM(L9:P9) -> 18 | R9: 38 | S9: 8 | T9: 6
A10: Tyler | B10: 45886 | C10: 83 | D10: 11 | E10: Rich | F10: =C10-D10 -> 72 | G10: Spring Lake Thunderbird | H10: Blue | I10: 6504 | J10: 42 | K10: 41 | L10: 0 | M10: 0 | N10: 10 | O10: 5 | P10: 3 | Q10: =SUM(L10:P10) -> 18 | R10: 30 | S10: 11 | T10: 4
A11: Rich | B11: 45886 | C11: 89 | D11: 17 | E11: Tyler | F11: =C11-D11 -> 72 | G11: Spring Lake Thunderbird | H11: Blue | I11: 6504 | J11: 45 | K11: 44 | L11: 0 | M11: 0 | N11: 7 | O11: 6 | P11: 5 | Q11: =SUM(L11:P11) -> 18 | R11: 39 | S11: 8 | T11: 8
A12: Tyler | B12: 45868 | C12: 81 | D12: 11 | E12: Vin | F12: =C12-D12 -> 70 | G12: Bethpage Red | H12: Blue | I12: 6921 | J12: 40 | K12: 41 | L12: 0 | M12: 1 | N12: 8 | O12: 6 | P12: 3 | Q12: =SUM(L12:P12) -> 18 | R12: 29 | S12: 7 | T12: 4
A13: Tyler | B13: 45857 | C13: 75 | D13: 4 | E13: Rich | F13: =C13-D13 -> 71 | G13: Bethpage Green | H13: White | I13: 6064 | J13: 38 | K13: 37 | L13: 0 | M13: 1 | N13: 12 | O13: 5 | P13: 0 | Q13: =SUM(L13:P13) -> 18 | R13: 33 | S13: 8 | T13: 11
A14: Rich | B14: 45857 | C14: 84 | D14: 13 | E14: Tyler | F14: =C14-D14 -> 71 | G14: Bethpage Green | H14: White | I14: 6124 | J14: 43 | L14: 0 | M14: 1 | N14: 8 | O14: 6 | P14: 3 | Q14: =SUM(L14:P14) -> 18 | R14: 35 | S14: 6 | T14: 8
A15: Ryan | B15: 45853 | C15: 109 | D15: 38 | F15: =C15-D15 -> 71 | G15: Pine Hollow | H15: White | I15: 6348 | J15: 57 | K15: 52 | L15: 0 | M15: 0 | N15: 1 | O15: 5 | P15: 12 | Q15: =SUM(L15:P15) -> 18 | R15: 45 | S15: 0 | T15: 2
A16: Tyler | B16: 45844 | C16: 79 | D16: 8 | E16: Rich | F16: =C16-D16 -> 71 | G16: Bethpage Green | H16: White | I16: 6064 | J16: 39 | K16: 40 | L16: 0 | M16: 0 | N16: 11 | O16: 6 | P16: 1 | Q16: =SUM(L16:P16) -> 18 | R16: 32 | S16: 7 | T16: 8
A17: Rich | B17: 45844 | C17: 86 | D17: 15 | E17: Tyler | F17: =C17-D17 -> 71 | G17: Bethpage Green | H17: White | I17: 6124 | J17: 44 | K17: 42 | L17: 0 | M17: 0 | N17: 6 | O17: 9 | P17: 3 | Q17: =SUM(L17:P17) -> 18 | R17: 31 | S17: 6 | T17: 3
A18: Tyler | B18: 45831 | C18: 78 | D18: 6 | E18: Vin | F18: =C18-D18 -> 72 | G18: Bethpage Blue | H18: Blue | I18: 6666 | J18: 41 | K18: 37 | L18: 0 | M18: 2 | N18: 9 | O18: 6 | P18: 1 | Q18: =SUM(L18:P18) -> 18 | R18: 32 | S18: 8 | T18: 8
A19: Tyler | B19: 45829 | C19: 76 | D19: 4 | E19: Rich | F19: =C19-D19 -> 72 | G19: Brentwood Country Club | H19: White | I19: 5835 | J19: 40 | K19: 36 | L19: 0 | M19: 2 | N19: 10 | O19: 6 | P19: 0 | Q19: =SUM(L19:P19) -> 18 | R19: 28 | S19: 9 | T19: 7
A20: Rich | B20: 45829 | C20: 83 | D20: 11 | E20: Tyler | F20: =C20-D20 -> 72 | G20: Brentwood Country Club | H20: White | I20: 5835 | J20: 45 | K20: 38 | L20: 0 | M20: 0 | N20: 8 | O20: 8 | P20: 2 | Q20: =SUM(L20:P20) -> 18 | R20: 34 | S20: 1 | T20: 6
A21: Ryan | B21: 45765 | C21: 111 | D21: 40 | F21: =C21-D21 -> 71 | G21: Cherry Creek | H21: White | I21: 6229 | J21: 58 | K21: 53 | L21: 0 | M21: 0 | N21: 2 | O21: 1 | P21: 15 | Q21: =SUM(L21:P21) -> 18 | R21: 42 | S21: 5 | T21: 2
A22: Tyler | B22: 45735 | C22: 76 | D22: 5 | E22: Vin | F22: =C22-D22 -> 71 | G22: Bethpage Green | H22: White | I22: 6124 | J22: 40 | K22: 36 | L22: 0 | M22: 1 | N22: 12 | O22: 4 | P22: 1 | Q22: =SUM(L22:P22) -> 18 | R22: 31 | S22: 7 | T22: 10
A23: Tyler | B23: 45655 | C23: 85 | D23: 13 | E23: Rich | F23: =C23-D23 -> 72 | G23: Wailea Golf Club Emerald Course | H23: Blue | I23: 6407 | J23: 42 | K23: 43 | L23: 0 | M23: 0 | N23: 8 | O23: 7 | P23: 3 | Q23: =SUM(L23:P23) -> 18 | R23: 34 | S23: 11 | T23: 6
A24: Rich | B24: 45655 | C24: 91 | D24: 19 | E24: Tyler | F24: =C24-D24 -> 72 | G24: Wailea Golf Club Emerald Course | H24: Blue | I24: 6407 | J24: 41 | K24: 50 | L24: 0 | M24: 0 | N24: 4 | O24: 9 | P24: 5 | Q24: =SUM(L24:P24) -> 18 | R24: 34 | S24: 11 | T24: 6
A25: Tyler | B25: 45653 | C25: 80 | D25: 8 | E25: Rich | F25: =C25-D25 -> 72 | G25: Wailea Golf Club Gold Course | H25: Blue | I25: 6653 | J25: 40 | K25: 40 | L25: 0 | M25: 0 | N25: 10 | O25: 8 | P25: 0 | Q25: =SUM(L25:P25) -> 18
A26: Rich | B26: 45653 | C26: 92 | D26: 20 | E26: Tyler | F26: =C26-D26 -> 72 | G26: Wailea Golf Club Gold Course | H26: Blue | I26: 6653 | J26: 46 | K26: 46 | L26: 0 | M26: 0 | N26: 2 | O26: 12 | P26: 4 | Q26: =SUM(L26:P26) -> 18 | R26: 36 | S26: 3 | T26: 2
A27: Tyler | B27: 45649 | C27: 88 | D27: 17 | E27: Rich | F27: =C27-D27 -> 71 | G27: Ka'anapali Golf Resort Royal Course | H27: Gold | I27: 5839 | J27: 47 | K27: 41 | L27: 0 | M27: 0 | N27: 3 | O27: 13 | P27: 2 | Q27: =SUM(L27:P27) -> 18 | R27: 35 | S27: 5 | T27: 1
A28: Rich | B28: 45649 | C28: 91 | D28: 20 | E28: Tyler | F28: =C28-D28 -> 71 | G28: Ka'anapali Golf Resort Royal Course | H28: Gold | I28: 5839 | J28: 47 | K28: 44 | L28: 0 | M28: 0 | N28: 2 | O28: 12 | P28: 4 | Q28: =SUM(L28:P28) -> 18 | R28: 37 | S28: 3 | T28: 3
A29: Tyler | B29: 45580 | C29: 83 | D29: 11 | E29: Rich, Ryan, Vin | F29: =C29-D29 -> 72 | G29: Sebonack Golf Club | H29: White | I29: 6409 | J29: 39 | K29: 44 | L29: 0 | M29: 2 | N29: 8 | O29: 3 | P29: 5 | Q29: =SUM(L29:P29) -> 18 | R29: 28 | S29: 5 | T29: 4
A30: Tyler | B30: 45570 | C30: 79 | D30: 8 | E30: Rich | F30: =C30-D30 -> 71 | G30: Bethpage Green | H30: White | I30: 6124 | J30: 38 | K30: 41 | L30: 0 | M30: 1 | N30: 9 | O30: 7 | P30: 1 | Q30: =SUM(L30:P30) -> 18 | R30: 29 | S30: 5 | T30: 5
A31: Rich | B31: 45570 | C31: 87 | D31: 16 | E31: Tyler | F31: =C31-D31 -> 71 | G31: Bethpage Green | H31: White | I31: 6064 | J31: 44 | K31: 43 | L31: 0 | M31: 0 | N31: 5 | O31: 10 | P31: 3 | Q31: =SUM(L31:P31) -> 18 | R31: 38 | S31: 2 | T31: 6
A32: Tyler | B32: 45535 | C32: 87 | D32: 16 | E32: Rich | F32: =C32-D32 -> 71 | G32: Bethpage Yellow | H32: White | I32: 6055 | J32: 45 | K32: 42 | L32: 0 | M32: 0 | N32: 4 | O32: 12 | P32: 2 | Q32: =SUM(L32:P32) -> 18 | R32: 32 | S32: 6 | T32: 3
A33: Rich | B33: 45535 | C33: 87 | D33: 16 | E33: Tyler | F33: =C33-D33 -> 71 | G33: Bethpage Yellow | H33: White | I33: 6022 | J33: 44 | K33: 43 | L33: 0 | M33: 0 | N33: 3 | O33: 14 | P33: 1 | Q33: =SUM(L33:P33) -> 18 | R33: 36 | S33: 4 | T33: 3
A34: Ryan | B34: 45520 | C34: 98 | D34: 27 | F34: =C34-D34 -> 71 | G34: Middle Island Country Club | H34: White | I34: 6549 | J34: 46 | K34: 52 | L34: 0 | M34: 0 | N34: 3 | O34: 8 | P34: 7 | Q34: =SUM(L34:P34) -> 18 | R34: 36 | S34: 7 | T34: 4
A35: Tyler | B35: 45514 | C35: 85 | D35: 13 | E35: Rich | F35: =C35-D35 -> 72 | G35: Brentwood Country Club | H35: Blue | I35: 6173 | J35: 45 | K35: 40 | L35: 0 | M35: 0 | N35: 7 | O35: 9 | P35: 2 | Q35: =SUM(L35:P35) -> 18 | R35: 31 | S35: 6 | T35: 4
A36: Rich | B36: 45514 | C36: 90 | D36: 18 | E36: Tyler | F36: =C36-D36 -> 72 | G36: Brentwood Country Club | H36: Blue | I36: 6173 | J36: 44 | K36: 46 | L36: 0 | M36: 0 | N36: 4 | O36: 10 | P36: 4 | Q36: =SUM(L36:P36) -> 18 | R36: 28 | S36: 4 | T36: 1
A37: Tyler | B37: 45502 | C37: 83 | D37: 12 | E37: Vin | F37: =C37-D37 -> 71 | G37: Bethpage Green | H37: Blue | I37: 6378 | J37: 41 | K37: 42 | L37: 0 | M37: 0 | N37: 8 | O37: 8 | P37: 2 | Q37: =SUM(L37:P37) -> 18 | R37: 29 | S37: 6 | T37: 4
A38: Tyler | B38: 45496 | C38: 79 | D38: 7 | E38: Chris | F38: =C38-D38 -> 72 | G38: Brentwood Country Club | H38: Blue | I38: 6173 | J38: 40 | K38: 39 | L38: 1 | M38: 2 | N38: 4 | O38: 11 | P38: 0 | Q38: =SUM(L38:P38) -> 18 | R38: 27 | S38: 9 | T38: 3
A39: Tyler | B39: 45492 | C39: 83 | D39: 11 | E39: Ryan | F39: =C39-D39 -> 72 | G39: Brentwood Country Club | H39: Blue | I39: 6173 | J39: 42 | K39: 41 | L39: 0 | M39: 1 | N39: 9 | O39: 4 | P39: 4 | Q39: =SUM(L39:P39) -> 18 | R39: 27 | S39: 8 | T39: 5
A40: Ryan | B40: 45492 | C40: 104 | D40: 32 | E40: Tyler | F40: =C40-D40 -> 72 | G40: Brentwood Country Club | H40: Blue | I40: 6173 | J40: 57 | K40: 47 | L40: 0 | M40: 1 | N40: 0 | O40: 6 | P40: 11 | Q40: =SUM(L40:P40) -> 18 | R40: 34 | S40: 7 | T40: 1
...

Sheet Handicap
A1: Golfer | B1: Date | C1: Course | D1: Tees | E1: Score | F1: Rating | G1: Slope | H1: Differential
A2: Tyler | B2: 45475 | C2: Bethpage Blue | D2: Blue | E2: 77 | F2: {=INDEX(CourseRatings[Rating], MATCH(1, (CourseRatings[Course]=C2)*(CourseRatings[Tees]=D2), 0))} -> 72.3 | G2: {=INDEX(CourseRatings[Slope], MATCH(1, (CourseRatings[Course]=C2)*(CourseRatings[Tees]=D2), 0))} -> 130 | H2: =(E2-F2)*113/G2 -> 4.0853846
A3: Tyler | B3: 45480 | C3: Bethpage Red | D3: Blue | E3: 80 | F3: {=INDEX(CourseRatings[Rating], MATCH(1, (CourseRatings[Course]=C3)*(CourseRatings[Tees]=D3), 0))} -> 74.4 | G3: {=INDEX(CourseRatings[Slope], MATCH(1, (CourseRatings[Course]=C3)*(CourseRatings[Tees]=D3), 0))} -> 133 | H3: =(E3-F3)*113/G3 -> 4.7578947
A4: Tyler | B4: 45831 | C4: Bethpage Blue | D4: Blue | E4: 78 | F4: {=INDEX(CourseRatings[Rating], MATCH(1, (CourseRatings[Course]=C4)*(CourseRatings[Tees]=D4), 0))} -> 72.3 | G4: {=INDEX(CourseRatings[Slope], MATCH(1, (CourseRatings[Course]=C4)*(CourseRatings[Tees]=D4), 0))} -> 130 | H4: =(E4-F4)*113/G4 -> 4.9546154
A5: Tyler | B5: 45857 | C5: Bethpage Green | D5: White | E5: 75 | F5: {=INDEX(CourseRatings[Rating], MATCH(1, (CourseRatings[Course]=C5)*(CourseRatings[Tees]=D5), 0))} -> 69.4 | G5: {=INDEX(CourseRatings[Slope], MATCH(1, (CourseRatings[Course]=C5)*(CourseRatings[Tees]=D5), 0))} -> 125 | H5: =(E5-F5)*113/G5 -> 5.0624
A6: Tyler | B6: 45868 | C6: Bethpage Red | D6: Blue | E6: 81 | F6: {=INDEX(CourseRatings[Rating], MATCH(1, (CourseRatings[Course]=C6)*(CourseRatings[Tees]=D6), 0))} -> 74.4 | G6: {=INDEX(CourseRatings[Slope], MATCH(1, (CourseRatings[Course]=C6)*(CourseRatings[Tees]=D6), 0))} -> 133 | H6: =(E6-F6)*113/G6 -> 5.6075188
A7: Tyler | B7: 45735 | C7: Bethpage Green | D7: White | E7: 76 | F7: {=INDEX(CourseRatings[Rating], MATCH(1, (CourseRatings[Course]=C7)*(CourseRatings[Tees]=D7), 0))} -> 69.4 | G7: {=INDEX(CourseRatings[Slope], MATCH(1, (CourseRatings[Course]=C7)*(CourseRatings[Tees]=D7), 0))} -> 125 | H7: =(E7-F7)*113/G7 -> 5.9664
A8: Tyler | B8: 45487 | C8: Bethpage Green | D8: Blue | E8: 78 | F8: {=INDEX(CourseRatings[Rating], MATCH(1, (CourseRatings[Course]=C8)*(CourseRatings[Tees]=D8), 0))} -> 70.2 | G8: {=INDEX(CourseRatings[Slope], MATCH(1, (CourseRatings[Course]=C8)*(CourseRatings[Tees]=D8), 0))} -> 129 | H8: =(E8-F8)*113/G8 -> 6.8325581
A9: Tyler | B9: 45467 | C9: Bethpage Blue | D9: White | E9: 80 | F9: {=INDEX(CourseRatings[Rating], MATCH(1, (CourseRatings[Course]=C9)*(CourseRatings[Tees]=D9), 0))} -> 71.3 | G9: {=INDEX(CourseRatings[Slope], MATCH(1, (CourseRatings[Course]=C9)*(CourseRatings[Tees]=D9), 0))} -> 127 | H9: =(E9-F9)*113/G9 -> 7.7409449
A10: Tyler | B10: 45829 | C10: Brentwood Country Club | D10: White | E10: 76 | F10: {=INDEX(CourseRatings[Rating], MATCH(1, (CourseRatings[Course]=C10)*(CourseRatings[Tees]=D10), 0))} -> 67.5 | G10: {=INDEX(CourseRatings[Slope], MATCH(1, (CourseRatings[Course]=C10)*(CourseRatings[Tees]=D10), 0))} -> 121 | H10: =(E10-F10)*113/G10 -> 7.9380165
A11: Tyler | B11: 45466 | C11: Bethpage Red | D11: White | E11: 81 | F11: {=INDEX(CourseRatings[Rating], MATCH(1, (CourseRatings[Course]=C11)*(CourseRatings[Tees]=D11), 0))} -> 71.9 | G11: {=INDEX(CourseRatings[Slope], MATCH(1, (CourseRatings[Course]=C11)*(CourseRatings[Tees]=D11), 0))} -> 127 | H11: =(E11-F11)*113/G11 -> 8.0968504
A12: Tyler | B12: 46160 | C12: Bethpage Blue | D12: Blue | E12: 82 | F12: {=INDEX(CourseRatings[Rating], MATCH(1, (CourseRatings[Course]=C12)*(CourseRatings[Tees]=D12), 0))} -> 72.3 | G12: {=INDEX(CourseRatings[Slope], MATCH(1, (CourseRatings[Course]=C12)*(CourseRatings[Tees]=D12), 0))} -> 130 | H12: =(E12-F12)*113/G12 -> 8.4315385
A13: Tyler | B13: 45496 | C13: Brentwood Country Club | D13: Blue | E13: 79 | F13: {=INDEX(CourseRatings[Rating], MATCH(1, (CourseRatings[Course]=C13)*(CourseRatings[Tees]=D13), 0))} -> 69.6 | G13: {=INDEX(CourseRatings[Slope], MATCH(1, (CourseRatings[Course]=C13)*(CourseRatings[Tees]=D13), 0))} -> 125 | H13: =(E13-F13)*113/G13 -> 8.4976
... A72: Ryan | B72: 46185 | C72: Swan Lake | D72: White | E72: 104 | F72: {=INDEX(CourseRatings[Rating], MATCH(1, (CourseRatings[Course]=C72)*(CourseRatings[Tees]=D72), 0))} -> 70.7 | G72: {=INDEX(CourseRatings[Slope], MATCH(1, (CourseRatings[Course]=C72)*(CourseRatings[Tees]=D72), 0))} -> 122 | H72: =(E72-F72)*113/G72 -> 30.843443
A75: Golfer | B75: Date | C75: Course | D75: Tees | E75: Score | F75: Rating | G75: Slope | H75: Differential
A76: Tyler | B76: 45457 | C76: Spring Lake Sandpiper Course | D76: Blue | E76: 44 | F76: {=INDEX(CourseRatings[Rating], MATCH(1, (CourseRatings[Course]=C76)*(CourseRatings[Tees]=D76), 0))} -> 33.9 | G76: {=INDEX(CourseRatings[Slope], MATCH(1, (CourseRatings[Course]=C76)*(CourseRatings[Tees]=D76), 0))} -> 122 | H76: =(E76-F76)*113/G76 -> 9.354918
A77: Tyler | B77: 45454 | C77: Bethpage Blue | D77: Blue | E77: 47 | F77: {=INDEX(CourseRatings[Rating], MATCH(1, (CourseRatings[Course]=C77)*(CourseRatings[Tees]=D77), 0))} -> 72.3 | G77: {=INDEX(CourseRatings[Slope], MATCH(1, (CourseRatings[Course]=C77)*(CourseRatings[Tees]=D77), 0))} -> 130 | H77: =(E77-F77)*113/G77 -> -21.991538

Sheet Hole Log
A1: Golfer | B1: Date | C1: Course | D1: Short Course | E1: Tees | F1: Score | G1: Holes | H1: Hole | I1: Yardage | J1: Handicap | K1: Par | L1: Hole Score | M1: Score vs Par | N1: Type | O1: Putts | P1: Fairways | Q1: GIR
A2: Tyler | B2: 45735 | C2: Bethpage Green | D2: Bethpage Green | E2: White | F2: 76 | G2: Hole 1 | H2: =VALUE(RIGHT(G2, LEN(G2) - 5)) -> 1 | I2: {=IFERROR(INDEX(CourseYardages[[Hole 1]:[Hole 18]], MATCH(1, (CourseYardages[Course]=C2)*(CourseYardages[Tees]=E2), 0), MATCH(G2, CourseYardages[[#Headers],[Hole 1]:[Hole 18]], 0) ),"")} -> 345 | J2: {=IFERROR(INDEX(CourseHandicap[[Hole 1]:[Hole 18]], MATCH(1, (CourseHandicap[Course]=C2)*(CourseHandicap[Tees]=E2), 0), MATCH(G2, CourseHandicap[[#Headers],[Hole 1]:[Hole 18]], 0) ),"")} -> 15 | K2: {=IFERROR(INDEX(CourseRatings[[Hole 1]:[Hole 18]], MATCH(1, (CourseRatings[Course]=C2)*(CourseRatings[Tees]=E2), 0), MATCH(G2, CourseRatings[[#Headers],[Hole 1]:[Hole 18]], 0) ),"")} -> 4 | L2: {=IFERROR( INDEX('Golf Log'!$E$2:$V$72, MATCH(1, ('Golf Log'!$A$2:$A$72=$A2)* ('Golf Log'!$B$2:$B$72=$B2)* ('Golf Log'!$C$2:$C$72=$C2), 0), MATCH($G2,'Golf Log'!$E$1:$V$1,0) ), "")} -> 4 | M2: =IFERROR(L2-K2,"") -> 0 | N2: =IF(M2="","",(IF(M2=-2,"Eagle",IF(M2=-1,"Birdie",IF(M2=0,"Par",IF(M2=1,"Bogey",IF(M2=2,"Double Bogey",IF(M2=3,"Triple Bogey",IF(M2>3,"Quad Bogey+"))))))))) -> Par | O2: {=IFERROR( INDEX('Putt Log'!$E$2:$V$72, MATCH(1, ('Putt Log'!$A$2:$A$72=$A2)* ('Putt Log'!$B$2:$B$72=$B2)* ('Putt Log'!$C$2:$C$72=$C2), 0), MATCH($G2,'Putt Log'!$E$1:$V$1,0) ), "")} -> 1 | P2: {=IF(K2=3,"", IFERROR( INDEX('Fairway Log'!$E$2:$V$72, MATCH(1, ('Fairway Log'!$A$2:$A$72=$A2)* ('Fairway Log'!$B$2:$B$72=$B2)* ('Fairway Log'!$C$2:$C72=$C2), 0), MATCH($G2,'Fairway Log'!$E$1:$V$1,0) ), "") )} -> 1 | Q2: {=IFERROR( INDEX('GIR Log'!$E$2:$V$72, MATCH(1, ('GIR Log'!$A$2:$A$72=$A2)* ('GIR Log'!$B$2:$B$72=$B2)* ('GIR Log'!$C$2:$C$72=$C2), 0), MATCH($G2,'GIR Log'!$E$1:$V$1,0) ), "")} -> ←
A3: Tyler | B3: 45735 | C3: Bethpage Green | D3: Bethpage Green | E3: White | F3: 76 | G3: Hole 2 | H3: =VALUE(RIGHT(G3, LEN(G3) - 5)) -> 2 | I3: {=IFERROR(INDEX(CourseYardages[[Hole 1]:[Hole 18]], MATCH(1, (CourseYardages[Course]=C3)*(CourseYardages[Tees]=E3), 0), MATCH(G3, CourseYardages[[#Headers],[Hole 1]:[Hole 18]], 0) ),"")} -> 367 | J3: {=IFERROR(INDEX(CourseHandicap[[Hole 1]:[Hole 18]], MATCH(1, (CourseHandicap[Course]=C3)*(CourseHandicap[Tees]=E3), 0), MATCH(G3, CourseHandicap[[#Headers],[Hole 1]:[Hole 18]], 0) ),"")} -> 3 | K3: {=IFERROR(INDEX(CourseRatings[[Hole 1]:[Hole 18]], MATCH(1, (CourseRatings[Course]=C3)*(CourseRatings[Tees]=E3), 0), MATCH(G3, CourseRatings[[#Headers],[Hole 1]:[Hole 18]], 0) ),"")} -> 4 | L3: {=IFERROR( INDEX('Golf Log'!$E$2:$V$72, MATCH(1, ('Golf Log'!$A$2:$A$72=$A3)* ('Golf Log'!$B$2:$B$72=$B3)* ('Golf Log'!$C$2:$C$72=$C3), 0), MATCH($G3,'Golf Log'!$E$1:$V$1,0) ), "")} -> 5 | M3: =IFERROR(L3-K3,"") -> 1 | N3: =IF(M3="","",(IF(M3=-2,"Eagle",IF(M3=-1,"Birdie",IF(M3=0,"Par",IF(M3=1,"Bogey",IF(M3=2,"Double Bogey",IF(M3=3,"Triple Bogey",IF(M3>3,"Quad Bogey+"))))))))) -> Bogey | O3: {=IFERROR( INDEX('Putt Log'!$E$2:$V$72, MATCH(1, ('Putt Log'!$A$2:$A$72=$A3)* ('Putt Log'!$B$2:$B$72=$B3)* ('Putt Log'!$C$2:$C$72=$C3), 0), MATCH($G3,'Putt Log'!$E$1:$V$1,0) ), "")} -> 2 | P3: {=IF(K3=3,"", IFERROR( INDEX('Fairway Log'!$E$2:$V$72, MATCH(1, ('Fairway Log'!$A$2:$A$72=$A3)* ('Fairway Log'!$B$2:$B$72=$B3)* ('Fairway Log'!$C$2:$C72=$C3), 0), MATCH($G3,'Fairway Log'!$E$1:$V$1,0) ), "") )} -> → | Q3: {=IFERROR( INDEX('GIR Log'!$E$2:$V$72, MATCH(1, ('GIR Log'!$A$2:$A$72=$A3)* ('GIR Log'!$B$2:$B$72=$B3)* ('GIR Log'!$C$2:$C$72=$C3), 0), MATCH($G3,'GIR Log'!$E$1:$V$1,0) ), "")} -> ↓
A4: Tyler | B4: 45735 | C4: Bethpage Green | D4: Bethpage Green | E4: White | F4: 76 | G4: Hole 3 | H4: =VALUE(RIGHT(G4, LEN(G4) - 5)) -> 3 | I4: {=IFERROR(INDEX(CourseYardages[[Hole 1]:[Hole 18]], MATCH(1, (CourseYardages[Course]=C4)*(CourseYardages[Tees]=E4), 0), MATCH(G4, CourseYardages[[#Headers],[Hole 1]:[Hole 18]], 0) ),"")} -> 133 | J4: {=IFERROR(INDEX(CourseHandicap[[Hole 1]:[Hole 18]], MATCH(1, (CourseHandicap[Course]=C4)*(CourseHandicap[Tees]=E4), 0), MATCH(G4, CourseHandicap[[#Headers],[Hole 1]:[Hole 18]], 0) ),"")} -> 17 | K4: {=IFERROR(INDEX(CourseRatings[[Hole 1]:[Hole 18]], MATCH(1, (CourseRatings[Course]=C4)*(CourseRatings[Tees]=E4), 0), MATCH(G4, CourseRatings[[#Headers],[Hole 1]:[Hole 18]], 0) ),"")} -> 3 | L4: {=IFERROR( INDEX('Golf Log'!$E$2:$V$72, MATCH(1, ('Golf Log'!$A$2:$A$72=$A4)* ('Golf Log'!$B$2:$B$72=$B4)* ('Golf Log'!$C$2:$C$72=$C4), 0), MATCH($G4,'Golf Log'!$E$1:$V$1,0) ), "")} -> 5 | M4: =IFERROR(L4-K4,"") -> 2 | N4: =IF(M4="","",(IF(M4=-2,"Eagle",IF(M4=-1,"Birdie",IF(M4=0,"Par",IF(M4=1,"Bogey",IF(M4=2,"Double Bogey",IF(M4=3,"Triple Bogey",IF(M4>3,"Quad Bogey+"))))))))) -> Double Bogey | O4: {=IFERROR( INDEX('Putt Log'!$E$2:$V$72, MATCH(1, ('Putt Log'!$A$2:$A$72=$A4)* ('Putt Log'!$B$2:$B$72=$B4)* ('Putt Log'!$C$2:$C$72=$C4), 0), MATCH($G4,'Putt Log'!$E$1:$V$1,0) ), "")} -> 2 | P4: {=IF(K4=3,"", IFERROR( INDEX('Fairway Log'!$E$2:$V$72, MATCH(1, ('Fairway Log'!$A$2:$A$72=$A4)* ('Fairway Log'!$B$2:$B$72=$B4)* ('Fairway Log'!$C$2:$C75=$C4), 0), MATCH($G4,'Fairway Log'!$E$1:$V$1,0) ), "") )} | Q4: {=IFERROR( INDEX('GIR Log'!$E$2:$V$72, MATCH(1, ('GIR Log'!$A$2:$A$72=$A4)* ('GIR Log'!$B$2:$B$72=$B4)* ('GIR Log'!$C$2:$C$72=$C4), 0), MATCH($G4,'GIR Log'!$E$1:$V$1,0) ), "")} -> ←
A5: Tyler | B5: 45735 | C5: Bethpage Green | D5: Bethpage Green | E5: White | F5: 76 | G5: Hole 4 | H5: =VALUE(RIGHT(G5, LEN(G5) - 5)) -> 4 | I5: {=IFERROR(INDEX(CourseYardages[[Hole 1]:[Hole 18]], MATCH(1, (CourseYardages[Course]=C5)*(CourseYardages[Tees]=E5), 0), MATCH(G5, CourseYardages[[#Headers],[Hole 1]:[Hole 18]], 0) ),"")} -> 344 | J5: {=IFERROR(INDEX(CourseHandicap[[Hole 1]:[Hole 18]], MATCH(1, (CourseHandicap[Course]=C5)*(CourseHandicap[Tees]=E5), 0), MATCH(G5, CourseHandicap[[#Headers],[Hole 1]:[Hole 18]], 0) ),"")} -> 11 | K5: {=IFERROR(INDEX(CourseRatings[[Hole 1]:[Hole 18]], MATCH(1, (CourseRatings[Course]=C5)*(CourseRatings[Tees]=E5), 0), MATCH(G5, CourseRatings[[#Headers],[Hole 1]:[Hole 18]], 0) ),"")} -> 4 | L5: {=IFERROR( INDEX('Golf Log'!$E$2:$V$72, MATCH(1, ('Golf Log'!$A$2:$A$72=$A5)* ('Golf Log'!$B$2:$B$72=$B5)* ('Golf Log'!$C$2:$C$72=$C5), 0), MATCH($G5,'Golf Log'!$E$1:$V$1,0) ), "")} -> 4 | M5: =IFERROR(L5-K5,"") -> 0 | N5: =IF(M5="","",(IF(M5=-2,"Eagle",IF(M5=-1,"Birdie",IF(M5=0,"Par",IF(M5=1,"Bogey",IF(M5=2,"Double Bogey",IF(M5=3,"Triple Bogey",IF(M5>3,"Quad Bogey+"))))))))) -> Par | O5: {=IFERROR( INDEX('Putt Log'!$E$2:$V$72, MATCH(1, ('Putt Log'!$A$2:$A$72=$A5)* ('Putt Log'!$B$2:$B$72=$B5)* ('Putt Log'!$C$2:$C$72=$C5), 0), MATCH($G5,'Putt Log'!$E$1:$V$1,0) ), "")} -> 2 | P5: {=IF(K5=3,"", IFERROR( INDEX('Fairway Log'!$E$2:$V$72, MATCH(1, ('Fairway Log'!$A$2:$A$72=$A5)* ('Fairway Log'!$B$2:$B$72=$B5)* ('Fairway Log'!$C$2:$C76=$C5), 0), MATCH($G5,'Fairway Log'!$E$1:$V$1,0) ), "") )} -> 1 | Q5: {=IFERROR( INDEX('GIR Log'!$E$2:$V$72, MATCH(1, ('GIR Log'!$A$2:$A$72=$A5)* ('GIR Log'!$B$2:$B$72=$B5)* ('GIR Log'!$C$2:$C$72=$C5), 0), MATCH($G5,'GIR Log'!$E$1:$V$1,0) ), "")} -> 1
A6: Tyler | B6: 45735 | C6: Bethpage Green | D6: Bethpage Green | E6: White | F6: 76 | G6: Hole 5 | H6: =VALUE(RIGHT(G6, LEN(G6) - 5)) -> 5 | I6: {=IFERROR(INDEX(CourseYardages[[Hole 1]:[Hole 18]], MATCH(1, (CourseYardages[Course]=C6)*(CourseYardages[Tees]=E6), 0), MATCH(G6, CourseYardages[[#Headers],[Hole 1]:[Hole 18]], 0) ),"")} -> 387 | J6: {=IFERROR(INDEX(CourseHandicap[[Hole 1]:[Hole 18]], MATCH(1, (CourseHandicap[Course]=C6)*(CourseHandicap[Tees]=E6), 0), MATCH(G6, CourseHandicap[[#Headers],[Hole 1]:[Hole 18]], 0) ),"")} -> 7 | K6: {=IFERROR(INDEX(CourseRatings[[Hole 1]:[Hole 18]], MATCH(1, (CourseRatings[Course]=C6)*(CourseRatings[Tees]=E6), 0), MATCH(G6, CourseRatings[[#Headers],[Hole 1]:[Hole 18]], 0) ),"")} -> 4 | L6: {=IFERROR( INDEX('Golf Log'!$E$2:$V$72, MATCH(1, ('Golf Log'!$A$2:$A$72=$A6)* ('Golf Log'!$B$2:$B$72=$B6)* ('Golf Log'!$C$2:$C$72=$C6), 0), MATCH($G6,'Golf Log'!$E$1:$V$1,0) ), "")} -> 5 | M6: =IFERROR(L6-K6,"") -> 1 | N6: =IF(M6="","",(IF(M6=-2,"Eagle",IF(M6=-1,"Birdie",IF(M6=0,"Par",IF(M6=1,"Bogey",IF(M6=2,"Double Bogey",IF(M6=3,"Triple Bogey",IF(M6>3,"Quad Bogey+"))))))))) -> Bogey | O6: {=IFERROR( INDEX('Putt Log'!$E$2:$V$72, MATCH(1, ('Putt Log'!$A$2:$A$72=$A6)* ('Putt Log'!$B$2:$B$72=$B6)* ('Putt Log'!$C$2:$C$72=$C6), 0), MATCH($G6,'Putt Log'!$E$1:$V$1,0) ), "")} -> 1 | P6: {=IF(K6=3,"", IFERROR( INDEX('Fairway Log'!$E$2:$V$72, MATCH(1, ('Fairway Log'!$A$2:$A$72=$A6)* ('Fairway Log'!$B$2:$B$72=$B6)* ('Fairway Log'!$C$2:$C77=$C6), 0), MATCH($G6,'Fairway Log'!$E$1:$V$1,0) ), "") )} -> ← | Q6: {=IFERROR( INDEX('GIR Log'!$E$2:$V$72, MATCH(1, ('GIR Log'!$A$2:$A$72=$A6)* ('GIR Log'!$B$2:$B$72=$B6)* ('GIR Log'!$C$2:$C$72=$C6), 0), MATCH($G6,'GIR Log'!$E$1:$V$1,0) ), "")} -> ←
A7: Tyler | B7: 45735 | C7: Bethpage Green | D7: Bethpage Green | E7: White | F7: 76 | G7: Hole 6 | H7: =VALUE(RIGHT(G7, LEN(G7) - 5)) -> 6 | I7: {=IFERROR(INDEX(CourseYardages[[Hole 1]:[Hole 18]], MATCH(1, (CourseYardages[Course]=C7)*(CourseYardages[Tees]=E7), 0), MATCH(G7, CourseYardages[[#Headers],[Hole 1]:[Hole 18]], 0) ),"")} -> 178 | J7: {=IFERROR(INDEX(CourseHandicap[[Hole 1]:[Hole 18]], MATCH(1, (CourseHandicap[Course]=C7)*(CourseHandicap[Tees]=E7), 0), MATCH(G7, CourseHandicap[[#Headers],[Hole 1]:[Hole 18]], 0) ),"")} -> 5 | K7: {=IFERROR(INDEX(CourseRatings[[Hole 1]:[Hole 18]], MATCH(1, (CourseRatings[Course]=C7)*(CourseRatings[Tees]=E7), 0), MATCH(G7, CourseRatings[[#Headers],[Hole 1]:[Hole 18]], 0) ),"")} -> 3 | L7: {=IFERROR( INDEX('Golf Log'!$E$2:$V$72, MATCH(1, ('Golf Log'!$A$2:$A$72=$A7)* ('Golf Log'!$B$2:$B$72=$B7)* ('Golf Log'!$C$2:$C$72=$C7), 0), MATCH($G7,'Golf Log'!$E$1:$V$1,0) ), "")} -> 3 | M7: =IFERROR(L7-K7,"") -> 0 | N7: =IF(M7="","",(IF(M7=-2,"Eagle",IF(M7=-1,"Birdie",IF(M7=0,"Par",IF(M7=1,"Bogey",IF(M7=2,"Double Bogey",IF(M7=3,"Triple Bogey",IF(M7>3,"Quad Bogey+"))))))))) -> Par | O7: {=IFERROR( INDEX('Putt Log'!$E$2:$V$72, MATCH(1, ('Putt Log'!$A$2:$A$72=$A7)* ('Putt Log'!$B$2:$B$72=$B7)* ('Putt Log'!$C$2:$C$72=$C7), 0), MATCH($G7,'Putt Log'!$E$1:$V$1,0) ), "")} -> 2 | P7: {=IF(K7=3,"", IFERROR( INDEX('Fairway Log'!$E$2:$V$72, MATCH(1, ('Fairway Log'!$A$2:$A$72=$A7)* ('Fairway Log'!$B$2:$B$72=$B7)* ('Fairway Log'!$C$2:$C78=$C7), 0), MATCH($G7,'Fairway Log'!$E$1:$V$1,0) ), "") )} | Q7: {=IFERROR( INDEX('GIR Log'!$E$2:$V$72, MATCH(1, ('GIR Log'!$A$2:$A$72=$A7)* ('GIR Log'!$B$2:$B$72=$B7)* ('GIR Log'!$C$2:$C$72=$C7), 0), MATCH($G7,'GIR Log'!$E$1:$V$1,0) ), "")} -> 1
A8: Tyler | B8: 45735 | C8: Bethpage Green | D8: Bethpage Green | E8: White | F8: 76 | G8: Hole 7 | H8: =VALUE(RIGHT(G8, LEN(G8) - 5)) -> 7 | I8: {=IFERROR(INDEX(CourseYardages[[Hole 1]:[Hole 18]], MATCH(1, (CourseYardages[Course]=C8)*(CourseYardages[Tees]=E8), 0), MATCH(G8, CourseYardages[[#Headers],[Hole 1]:[Hole 18]], 0) ),"")} -> 500 | J8: {=IFERROR(INDEX(CourseHandicap[[Hole 1]:[Hole 18]], MATCH(1, (CourseHandicap[Course]=C8)*(CourseHandicap[Tees]=E8), 0), MATCH(G8, CourseHandicap[[#Headers],[Hole 1]:[Hole 18]], 0) ),"")} -> 9 | K8: {=IFERROR(INDEX(CourseRatings[[Hole 1]:[Hole 18]], MATCH(1, (CourseRatings[Course]=C8)*(CourseRatings[Tees]=E8), 0), MATCH(G8, CourseRatings[[#Headers],[Hole 1]:[Hole 18]], 0) ),"")} -> 5 | L8: {=IFERROR( INDEX('Golf Log'!$E$2:$V$72, MATCH(1, ('Golf Log'!$A$2:$A$72=$A8)* ('Golf Log'!$B$2:$B$72=$B8)* ('Golf Log'!$C$2:$C$72=$C8), 0), MATCH($G8,'Golf Log'!$E$1:$V$1,0) ), "")} -> 6 | M8: =IFERROR(L8-K8,"") -> 1 | N8: =IF(M8="","",(IF(M8=-2,"Eagle",IF(M8=-1,"Birdie",IF(M8=0,"Par",IF(M8=1,"Bogey",IF(M8=2,"Double Bogey",IF(M8=3,"Triple Bogey",IF(M8>3,"Quad Bogey+"))))))))) -> Bogey | O8: {=IFERROR( INDEX('Putt Log'!$E$2:$V$72, MATCH(1, ('Putt Log'!$A$2:$A$72=$A8)* ('Putt Log'!$B$2:$B$72=$B8)* ('Putt Log'!$C$2:$C$72=$C8), 0), MATCH($G8,'Putt Log'!$E$1:$V$1,0) ), "")} -> 2 | P8: {=IF(K8=3,"", IFERROR( INDEX('Fairway Log'!$E$2:$V$72, MATCH(1, ('Fairway Log'!$A$2:$A$72=$A8)* ('Fairway Log'!$B$2:$B$72=$B8)* ('Fairway Log'!$C$2:$C79=$C8), 0), MATCH($G8,'Fairway Log'!$E$1:$V$1,0) ), "") )} -> ← | Q8: {=IFERROR( INDEX('GIR Log'!$E$2:$V$72, MATCH(1, ('GIR Log'!$A$2:$A$72=$A8)* ('GIR Log'!$B$2:$B$72=$B8)* ('GIR Log'!$C$2:$C$72=$C8), 0), MATCH($G8,'GIR Log'!$E$1:$V$1,0) ), "")} -> ↓
A9: Tyler | B9: 45735 | C9: Bethpage Green | D9: Bethpage Green | E9: White | F9: 76 | G9: Hole 8 | H9: =VALUE(RIGHT(G9, LEN(G9) - 5)) -> 8 | I9: {=IFERROR(INDEX(CourseYardages[[Hole 1]:[Hole 18]], MATCH(1, (CourseYardages[Course]=C9)*(CourseYardages[Tees]=E9), 0), MATCH(G9, CourseYardages[[#Headers],[Hole 1]:[Hole 18]], 0) ),"")} -> 337 | J9: {=IFERROR(INDEX(CourseHandicap[[Hole 1]:[Hole 18]], MATCH(1, (CourseHandicap[Course]=C9)*(CourseHandicap[Tees]=E9), 0), MATCH(G9, CourseHandicap[[#Headers],[Hole 1]:[Hole 18]], 0) ),"")} -> 13 | K9: {=IFERROR(INDEX(CourseRatings[[Hole 1]:[Hole 18]], MATCH(1, (CourseRatings[Course]=C9)*(CourseRatings[Tees]=E9), 0), MATCH(G9, CourseRatings[[#Headers],[Hole 1]:[Hole 18]], 0) ),"")} -> 4 | L9: {=IFERROR( INDEX('Golf Log'!$E$2:$V$72, MATCH(1, ('Golf Log'!$A$2:$A$72=$A9)* ('Golf Log'!$B$2:$B$72=$B9)* ('Golf Log'!$C$2:$C$72=$C9), 0), MATCH($G9,'Golf Log'!$E$1:$V$1,0) ), "")} -> 3 | M9: =IFERROR(L9-K9,"") -> -1 | N9: =IF(M9="","",(IF(M9=-2,"Eagle",IF(M9=-1,"Birdie",IF(M9=0,"Par",IF(M9=1,"Bogey",IF(M9=2,"Double Bogey",IF(M9=3,"Triple Bogey",IF(M9>3,"Quad Bogey+"))))))))) -> Birdie | O9: {=IFERROR( INDEX('Putt Log'!$E$2:$V$72, MATCH(1, ('Putt Log'!$A$2:$A$72=$A9)* ('Putt Log'!$B$2:$B$72=$B9)* ('Putt Log'!$C$2:$C$72=$C9), 0), MATCH($G9,'Putt Log'!$E$1:$V$1,0) ), "")} -> 1 | P9: {=IF(K9=3,"", IFERROR( INDEX('Fairway Log'!$E$2:$V$72, MATCH(1, ('Fairway Log'!$A$2:$A$72=$A9)* ('Fairway Log'!$B$2:$B$72=$B9)* ('Fairway Log'!$C$2:$C80=$C9), 0), MATCH($G9,'Fairway Log'!$E$1:$V$1,0) ), "") )} -> 1 | Q9: {=IFERROR( INDEX('GIR Log'!$E$2:$V$72, MATCH(1, ('GIR Log'!$A$2:$A$72=$A9)* ('GIR Log'!$B$2:$B$72=$B9)* ('GIR Log'!$C$2:$C$72=$C9), 0), MATCH($G9,'GIR Log'!$E$1:$V$1,0) ), "")} -> 1
A10: Tyler | B10: 45735 | C10: Bethpage Green | D10: Bethpage Green | E10: White | F10: 76 | G10: Hole 9 | H10: =VALUE(RIGHT(G10, LEN(G10) - 5)) -> 9 | I10: {=IFERROR(INDEX(CourseYardages[[Hole 1]:[Hole 18]], MATCH(1, (CourseYardages[Course]=C10)*(CourseYardages[Tees]=E10), 0), MATCH(G10, CourseYardages[[#Headers],[Hole 1]:[Hole 18]], 0) ),"")} -> 532 | J10: {=IFERROR(INDEX(CourseHandicap[[Hole 1]:[Hole 18]], MATCH(1, (CourseHandicap[Course]=C10)*(CourseHandicap[Tees]=E10), 0), MATCH(G10, CourseHandicap[[#Headers],[Hole 1]:[Hole 18]], 0) ),"")} -> 1 | K10: {=IFERROR(INDEX(CourseRatings[[Hole 1]:[Hole 18]], MATCH(1, (CourseRatings[Course]=C10)*(CourseRatings[Tees]=E10), 0), MATCH(G10, CourseRatings[[#Headers],[Hole 1]:[Hole 18]], 0) ),"")} -> 5 | L10: {=IFERROR( INDEX('Golf Log'!$E$2:$V$72, MATCH(1, ('Golf Log'!$A$2:$A$72=$A10)* ('Golf Log'!$B$2:$B$72=$B10)* ('Golf Log'!$C$2:$C$72=$C10), 0), MATCH($G10,'Golf Log'!$E$1:$V$1,0) ), "")} -> 5 | M10: =IFERROR(L10-K10,"") -> 0 | N10: =IF(M10="","",(IF(M10=-2,"Eagle",IF(M10=-1,"Birdie",IF(M10=0,"Par",IF(M10=1,"Bogey",IF(M10=2,"Double Bogey",IF(M10=3,"Triple Bogey",IF(M10>3,"Quad Bogey+"))))))))) -> Par | O10: {=IFERROR( INDEX('Putt Log'!$E$2:$V$72, MATCH(1, ('Putt Log'!$A$2:$A$72=$A10)* ('Putt Log'!$B$2:$B$72=$B10)* ('Putt Log'!$C$2:$C$72=$C10), 0), MATCH($G10,'Putt Log'!$E$1:$V$1,0) ), "")} -> 2 | P10: {=IF(K10=3,"", IFERROR( INDEX('Fairway Log'!$E$2:$V$72, MATCH(1, ('Fairway Log'!$A$2:$A$72=$A10)* ('Fairway Log'!$B$2:$B$72=$B10)* ('Fairway Log'!$C$2:$C81=$C10), 0), MATCH($G10,'Fairway Log'!$E$1:$V$1,0) ), "") )} -> 1 | Q10: {=IFERROR( INDEX('GIR Log'!$E$2:$V$72, MATCH(1, ('GIR Log'!$A$2:$A$72=$A10)* ('GIR Log'!$B$2:$B$72=$B10)* ('GIR Log'!$C$2:$C$72=$C10), 0), MATCH($G10,'GIR Log'!$E$1:$V$1,0) ), "")} -> 1
A11: Tyler | B11: 45735 | C11: Bethpage Green | D11: Bethpage Green | E11: White | F11: 76 | G11: Hole 10 | H11: =VALUE(RIGHT(G11, LEN(G11) - 5)) -> 10 | I11: {=IFERROR(INDEX(CourseYardages[[Hole 1]:[Hole 18]], MATCH(1, (CourseYardages[Course]=C11)*(CourseYardages[Tees]=E11), 0), MATCH(G11, CourseYardages[[#Headers],[Hole 1]:[Hole 18]], 0) ),"")} -> 328 | J11: {=IFERROR(INDEX(CourseHandicap[[Hole 1]:[Hole 18]], MATCH(1, (CourseHandicap[Course]=C11)*(CourseHandicap[Tees]=E11), 0), MATCH(G11, CourseHandicap[[#Headers],[Hole 1]:[Hole 18]], 0) ),"")} -> 12 | K11: {=IFERROR(INDEX(CourseRatings[[Hole 1]:[Hole 18]], MATCH(1, (CourseRatings[Course]=C11)*(CourseRatings[Tees]=E11), 0), MATCH(G11, CourseRatings[[#Headers],[Hole 1]:[Hole 18]], 0) ),"")} -> 4 | L11: {=IFERROR( INDEX('Golf Log'!$E$2:$V$72, MATCH(1, ('Golf Log'!$A$2:$A$72=$A11)* ('Golf Log'!$B$2:$B$72=$B11)* ('Golf Log'!$C$2:$C$72=$C11), 0), MATCH($G11,'Golf Log'!$E$1:$V$1,0) ), "")} -> 4 | M11: =IFERROR(L11-K11,"") -> 0 | N11: =IF(M11="","",(IF(M11=-2,"Eagle",IF(M11=-1,"Birdie",IF(M11=0,"Par",IF(M11=1,"Bogey",IF(M11=2,"Double Bogey",IF(M11=3,"Triple Bogey",IF(M11>3,"Quad Bogey+"))))))))) -> Par | O11: {=IFERROR( INDEX('Putt Log'!$E$2:$V$72, MATCH(1, ('Putt Log'!$A$2:$A$72=$A11)* ('Putt Log'!$B$2:$B$72=$B11)* ('Putt Log'!$C$2:$C$72=$C11), 0), MATCH($G11,'Putt Log'!$E$1:$V$1,0) ), "")} -> 2 | P11: {=IF(K11=3,"", IFERROR( INDEX('Fairway Log'!$E$2:$V$72, MATCH(1, ('Fairway Log'!$A$2:$A$72=$A11)* ('Fairway Log'!$B$2:$B$72=$B11)* ('Fairway Log'!$C$2:$C82=$C11), 0), MATCH($G11,'Fairway Log'!$E$1:$V$1,0) ), "") )} -> → | Q11: {=IFERROR( INDEX('GIR Log'!$E$2:$V$72, MATCH(1, ('GIR Log'!$A$2:$A$72=$A11)* ('GIR Log'!$B$2:$B$72=$B11)* ('GIR Log'!$C$2:$C$72=$C11), 0), MATCH($G11,'GIR Log'!$E$1:$V$1,0) ), "")} -> 1
A12: Tyler | B12: 45735 | C12: Bethpage Green | D12: Bethpage Green | E12: White | F12: 76 | G12: Hole 11 | H12: =VALUE(RIGHT(G12, LEN(G12) - 5)) -> 11 | I12: {=IFERROR(INDEX(CourseYardages[[Hole 1]:[Hole 18]], MATCH(1, (CourseYardages[Course]=C12)*(CourseYardages[Tees]=E12), 0), MATCH(G12, CourseYardages[[#Headers],[Hole 1]:[Hole 18]], 0) ),"")} -> 159 | J12: {=IFERROR(INDEX(CourseHandicap[[Hole 1]:[Hole 18]], MATCH(1, (CourseHandicap[Course]=C12)*(CourseHandicap[Tees]=E12), 0), MATCH(G12, CourseHandicap[[#Headers],[Hole 1]:[Hole 18]], 0) ),"")} -> 16 | K12: {=IFERROR(INDEX(CourseRatings[[Hole 1]:[Hole 18]], MATCH(1, (CourseRatings[Course]=C12)*(CourseRatings[Tees]=E12), 0), MATCH(G12, CourseRatings[[#Headers],[Hole 1]:[Hole 18]], 0) ),"")} -> 3 | L12: {=IFERROR( INDEX('Golf Log'!$E$2:$V$72, MATCH(1, ('Golf Log'!$A$2:$A$72=$A12)* ('Golf Log'!$B$2:$B$72=$B12)* ('Golf Log'!$C$2:$C$72=$C12), 0), MATCH($G12,'Golf Log'!$E$1:$V$1,0) ), "")} -> 4 | M12: =IFERROR(L12-K12,"") -> 1 | N12: =IF(M12="","",(IF(M12=-2,"Eagle",IF(M12=-1,"Birdie",IF(M12=0,"Par",IF(M12=1,"Bogey",IF(M12=2,"Double Bogey",IF(M12=3,"Triple Bogey",IF(M12>3,"Quad Bogey+"))))))))) -> Bogey | O12: {=IFERROR( INDEX('Putt Log'!$E$2:$V$72, MATCH(1, ('Putt Log'!$A$2:$A$72=$A12)* ('Putt Log'!$B$2:$B$72=$B12)* ('Putt Log'!$C$2:$C$72=$C12), 0), MATCH($G12,'Putt Log'!$E$1:$V$1,0) ), "")} -> 2 | P12: {=IF(K12=3,"", IFERROR( INDEX('Fairway Log'!$E$2:$V$72, MATCH(1, ('Fairway Log'!$A$2:$A$72=$A12)* ('Fairway Log'!$B$2:$B$72=$B12)* ('Fairway Log'!$C$2:$C83=$C12), 0), MATCH($G12,'Fairway Log'!$E$1:$V$1,0) ), "") )} | Q12: {=IFERROR( INDEX('GIR Log'!$E$2:$V$72, MATCH(1, ('GIR Log'!$A$2:$A$72=$A12)* ('GIR Log'!$B$2:$B$72=$B12)* ('GIR Log'!$C$2:$C$72=$C12), 0), MATCH($G12,'GIR Log'!$E$1:$V$1,0) ), "")} -> →
A13: Tyler | B13: 45735 | C13: Bethpage Green | D13: Bethpage Green | E13: White | F13: 76 | G13: Hole 12 | H13: =VALUE(RIGHT(G13, LEN(G13) - 5)) -> 12 | I13: {=IFERROR(INDEX(CourseYardages[[Hole 1]:[Hole 18]], MATCH(1, (CourseYardages[Course]=C13)*(CourseYardages[Tees]=E13), 0), MATCH(G13, CourseYardages[[#Headers],[Hole 1]:[Hole 18]], 0) ),"")} -> 279 | J13: {=IFERROR(INDEX(CourseHandicap[[Hole 1]:[Hole 18]], MATCH(1, (CourseHandicap[Course]=C13)*(CourseHandicap[Tees]=E13), 0), MATCH(G13, CourseHandicap[[#Headers],[Hole 1]:[Hole 18]], 0) ),"")} -> 18 | K13: {=IFERROR(INDEX(CourseRatings[[Hole 1]:[Hole 18]], MATCH(1, (CourseRatings[Course]=C13)*(CourseRatings[Tees]=E13), 0), MATCH(G13, CourseRatings[[#Headers],[Hole 1]:[Hole 18]], 0) ),"")} -> 4 | L13: {=IFERROR( INDEX('Golf Log'!$E$2:$V$72, MATCH(1, ('Golf Log'!$A$2:$A$72=$A13)* ('Golf Log'!$B$2:$B$72=$B13)* ('Golf Log'!$C$2:$C$72=$C13), 0), MATCH($G13,'Golf Log'!$E$1:$V$1,0) ), "")} -> 4 | M13: =IFERROR(L13-K13,"") -> 0 | N13: =IF(M13="","",(IF(M13=-2,"Eagle",IF(M13=-1,"Birdie",IF(M13=0,"Par",IF(M13=1,"Bogey",IF(M13=2,"Double Bogey",IF(M13=3,"Triple Bogey",IF(M13>3,"Quad Bogey+"))))))))) -> Par | O13: {=IFERROR( INDEX('Putt Log'!$E$2:$V$72, MATCH(1, ('Putt Log'!$A$2:$A$72=$A13)* ('Putt Log'!$B$2:$B$72=$B13)* ('Putt Log'!$C$2:$C$72=$C13), 0), MATCH($G13,'Putt Log'!$E$1:$V$1,0) ), "")} -> 2 | P13: {=IF(K13=3,"", IFERROR( INDEX('Fairway Log'!$E$2:$V$72, MATCH(1, ('Fairway Log'!$A$2:$A$72=$A13)* ('Fairway Log'!$B$2:$B$72=$B13)* ('Fairway Log'!$C$2:$C84=$C13), 0), MATCH($G13,'Fairway Log'!$E$1:$V$1,0) ), "") )} -> 1 | Q13: {=IFERROR( INDEX('GIR Log'!$E$2:$V$72, MATCH(1, ('GIR Log'!$A$2:$A$72=$A13)* ('GIR Log'!$B$2:$B$72=$B13)* ('GIR Log'!$C$2:$C$72=$C13), 0), MATCH($G13,'GIR Log'!$E$1:$V$1,0) ), "")} -> 1
A14: Tyler | B14: 45735 | C14: Bethpage Green | D14: Bethpage Green | E14: White | F14: 76 | G14: Hole 13 | H14: =VALUE(RIGHT(G14, LEN(G14) - 5)) -> 13 | I14: {=IFERROR(INDEX(CourseYardages[[Hole 1]:[Hole 18]], MATCH(1, (CourseYardages[Course]=C14)*(CourseYardages[Tees]=E14), 0), MATCH(G14, CourseYardages[[#Headers],[Hole 1]:[Hole 18]], 0) ),"")} -> 553 | J14: {=IFERROR(INDEX(CourseHandicap[[Hole 1]:[Hole 18]], MATCH(1, (CourseHandicap[Course]=C14)*(CourseHandicap[Tees]=E14), 0), MATCH(G14, CourseHandicap[[#Headers],[Hole 1]:[Hole 18]], 0) ),"")} -> 2 | K14: {=IFERROR(INDEX(CourseRatings[[Hole 1]:[Hole 18]], MATCH(1, (CourseRatings[Course]=C14)*(CourseRatings[Tees]=E14), 0), MATCH(G14, CourseRatings[[#Headers],[Hole 1]:[Hole 18]], 0) ),"")} -> 5 | L14: {=IFERROR( INDEX('Golf Log'!$E$2:$V$72, MATCH(1, ('Golf Log'!$A$2:$A$72=$A14)* ('Golf Log'!$B$2:$B$72=$B14)* ('Golf Log'!$C$2:$C$72=$C14), 0), MATCH($G14,'Golf Log'!$E$1:$V$1,0) ), "")} -> 5 | M14: =IFERROR(L14-K14,"") -> 0 | N14: =IF(M14="","",(IF(M14=-2,"Eagle",IF(M14=-1,"Birdie",IF(M14=0,"Par",IF(M14=1,"Bogey",IF(M14=2,"Double Bogey",IF(M14=3,"Triple Bogey",IF(M14>3,"Quad Bogey+"))))))))) -> Par | O14: {=IFERROR( INDEX('Putt Log'!$E$2:$V$72, MATCH(1, ('Putt Log'!$A$2:$A$72=$A14)* ('Putt Log'!$B$2:$B$72=$B14)* ('Putt Log'!$C$2:$C$72=$C14), 0), MATCH($G14,'Putt Log'!$E$1:$V$1,0) ), "")} -> 2 | P14: {=IF(K14=3,"", IFERROR( INDEX('Fairway Log'!$E$2:$V$72, MATCH(1, ('Fairway Log'!$A$2:$A$72=$A14)* ('Fairway Log'!$B$2:$B$72=$B14)* ('Fairway Log'!$C$2:$C85=$C14), 0), MATCH($G14,'Fairway Log'!$E$1:$V$1,0) ), "") )} -> 1 | Q14: {=IFERROR( INDEX('GIR Log'!$E$2:$V$72, MATCH(1, ('GIR Log'!$A$2:$A$72=$A14)* ('GIR Log'!$B$2:$B$72=$B14)* ('GIR Log'!$C$2:$C$72=$C14), 0), MATCH($G14,'GIR Log'!$E$1:$V$1,0) ), "")} -> 1
A15: Tyler | B15: 45735 | C15: Bethpage Green | D15: Bethpage Green | E15: White | F15: 76 | G15: Hole 14 | H15: =VALUE(RIGHT(G15, LEN(G15) - 5)) -> 14 | I15: {=IFERROR(INDEX(CourseYardages[[Hole 1]:[Hole 18]], MATCH(1, (CourseYardages[Course]=C15)*(CourseYardages[Tees]=E15), 0), MATCH(G15, CourseYardages[[#Headers],[Hole 1]:[Hole 18]], 0) ),"")} -> 352 | J15: {=IFERROR(INDEX(CourseHandicap[[Hole 1]:[Hole 18]], MATCH(1, (CourseHandicap[Course]=C15)*(CourseHandicap[Tees]=E15), 0), MATCH(G15, CourseHandicap[[#Headers],[Hole 1]:[Hole 18]], 0) ),"")} -> 14 | K15: {=IFERROR(INDEX(CourseRatings[[Hole 1]:[Hole 18]], MATCH(1, (CourseRatings[Course]=C15)*(CourseRatings[Tees]=E15), 0), MATCH(G15, CourseRatings[[#Headers],[Hole 1]:[Hole 18]], 0) ),"")} -> 4 | L15: {=IFERROR( INDEX('Golf Log'!$E$2:$V$72, MATCH(1, ('Golf Log'!$A$2:$A$72=$A15)* ('Golf Log'!$B$2:$B$72=$B15)* ('Golf Log'!$C$2:$C$72=$C15), 0), MATCH($G15,'Golf Log'!$E$1:$V$1,0) ), "")} -> 4 | M15: =IFERROR(L15-K15,"") -> 0 | N15: =IF(M15="","",(IF(M15=-2,"Eagle",IF(M15=-1,"Birdie",IF(M15=0,"Par",IF(M15=1,"Bogey",IF(M15=2,"Double Bogey",IF(M15=3,"Triple Bogey",IF(M15>3,"Quad Bogey+"))))))))) -> Par | O15: {=IFERROR( INDEX('Putt Log'!$E$2:$V$72, MATCH(1, ('Putt Log'!$A$2:$A$72=$A15)* ('Putt Log'!$B$2:$B$72=$B15)* ('Putt Log'!$C$2:$C$72=$C15), 0), MATCH($G15,'Putt Log'!$E$1:$V$1,0) ), "")} -> 2 | P15: {=IF(K15=3,"", IFERROR( INDEX('Fairway Log'!$E$2:$V$72, MATCH(1, ('Fairway Log'!$A$2:$A$72=$A15)* ('Fairway Log'!$B$2:$B$72=$B15)* ('Fairway Log'!$C$2:$C86=$C15), 0), MATCH($G15,'Fairway Log'!$E$1:$V$1,0) ), "") )} -> → | Q15: {=IFERROR( INDEX('GIR Log'!$E$2:$V$72, MATCH(1, ('GIR Log'!$A$2:$A$72=$A15)* ('GIR Log'!$B$2:$B$72=$B15)* ('GIR Log'!$C$2:$C$72=$C15), 0), MATCH($G15,'GIR Log'!$E$1:$V$1,0) ), "")} -> 1
... A1261: Ryan | B1261: 46185 | C1261: Swan Lake | D1261: Swan Lake | E1261: White | F1261: 104 | G1261: Hole 18 | H1261: =VALUE(RIGHT(G1261, LEN(G1261) - 5)) -> 18 | I1261: {=IFERROR(INDEX(CourseYardages[[Hole 1]:[Hole 18]], MATCH(1, (CourseYardages[Course]=C1261)*(CourseYardages[Tees]=E1261), 0), MATCH(G1261, CourseYardages[[#Headers],[Hole 1]:[Hole 18]], 0) ),"")} -> 354 | J1261: {=IFERROR(INDEX(CourseHandicap[[Hole 1]:[Hole 18]], MATCH(1, (CourseHandicap[Course]=C1261)*(CourseHandicap[Tees]=E1261), 0), MATCH(G1261, CourseHandicap[[#Headers],[Hole 1]:[Hole 18]], 0) ),"")} -> 2 | K1261: {=IFERROR(INDEX(CourseRatings[[Hole 1]:[Hole 18]], MATCH(1, (CourseRatings[Course]=C1261)*(CourseRatings[Tees]=E1261), 0), MATCH(G1261, CourseRatings[[#Headers],[Hole 1]:[Hole 18]], 0) ),"")} -> 4 | L1261: {=IFERROR( INDEX('Golf Log'!$E$2:$V$72, MATCH(1, ('Golf Log'!$A$2:$A$72=$A1261)* ('Golf Log'!$B$2:$B$72=$B1261)* ('Golf Log'!$C$2:$C$72=$C1261), 0), MATCH($G1261,'Golf Log'!$E$1:$V$1,0) ), "")} -> 7 | M1261: =IFERROR(L1261-K1261,"") -> 3 | N1261: =IF(M1261="","",(IF(M1261=-2,"Eagle",IF(M1261=-1,"Birdie",IF(M1261=0,"Par",IF(M1261=1,"Bogey",IF(M1261=2,"Double Bogey",IF(M1261=3,"Triple Bogey",IF(M1261>3,"Quad Bogey+"))))))))) -> Triple Bogey | O1261: {=IFERROR( INDEX('Putt Log'!$E$2:$V$72, MATCH(1, ('Putt Log'!$A$2:$A$72=$A1261)* ('Putt Log'!$B$2:$B$72=$B1261)* ('Putt Log'!$C$2:$C$72=$C1261), 0), MATCH($G1261,'Putt Log'!$E$1:$V$1,0) ), "")} -> 2 | P1261: {=IF(K1261=3,"", IFERROR( INDEX('Fairway Log'!$E$2:$V$72, MATCH(1, ('Fairway Log'!$A$2:$A$72=$A1261)* ('Fairway Log'!$B$2:$B$72=$B1261)* ('Fairway Log'!$C$2:$C1332=$C1261), 0), MATCH($G1261,'Fairway Log'!$E$1:$V$1,0) ), "") )} -> → | Q1261: {=IFERROR( INDEX('GIR Log'!$E$2:$V$72, MATCH(1, ('GIR Log'!$A$2:$A$72=$A1261)* ('GIR Log'!$B$2:$B$72=$B1261)* ('GIR Log'!$C$2:$C$72=$C1261), 0), MATCH($G1261,'GIR Log'!$E$1:$V$1,0) ), "")} -> ↓

Sheet Golf Log
A1: Golfer | B1: Date | C1: Course | D1: Score | E1: Hole 1 | F1: Hole 2 | G1: Hole 3 | H1: Hole 4 | I1: Hole 5 | J1: Hole 6 | K1: Hole 7 | L1: Hole 8 | M1: Hole 9 | N1: Hole 10 | O1: Hole 11 | P1: Hole 12 | Q1: Hole 13 | R1: Hole 14 | S1: Hole 15 | T1: Hole 16 | U1: Hole 17 | V1: Hole 18 | W1: Putts | X1: Fairways | Y1: GIR | Z1: Par 3 Avg | AA1: Par 4 Avg | AB1: Par 5 Avg
A2: Tyler | B2: 45735 | C2: Bethpage Green | D2: =SUM('Golf Log'!$E2:$V2) -> 76 | E2: 4 | F2: 5 | G2: 5 | H2: 4 | I2: 5 | J2: 3 | K2: 6 | L2: 3 | M2: 5 | N2: 4 | O2: 4 | P2: 4 | Q2: 5 | R2: 4 | S2: 3 | T2: 4 | U2: 4 | V2: 4 | W2: 31 | X2: 7 | Y2: 10 | Z2: {=SUMPRODUCT((_xlfn.XLOOKUP(C2, 'Course Stats'!A:A, 'Course Stats'!G:X)=3)*(E2:V2)) / COUNTIF(_xlfn.XLOOKUP(C2, 'Course Stats'!A:A, 'Course Stats'!G:X), 3)} -> 3.75 | AA2: {=SUMPRODUCT((_xlfn.XLOOKUP(C2, 'Course Stats'!A:A, 'Course Stats'!G:X)=4)*(E2:V2)) / COUNTIF(_xlfn.XLOOKUP(C2, 'Course Stats'!A:A, 'Course Stats'!G:X), 4)} -> 4.0909091 | AB2: {=SUMPRODUCT((_xlfn.XLOOKUP(C2, 'Course Stats'!A:A, 'Course Stats'!G:X)=5)*(E2:V2)) / COUNTIF(_xlfn.XLOOKUP(C2, 'Course Stats'!A:A, 'Course Stats'!G:X), 5)} -> 5.3333333
A3: Tyler | B3: 45655 | C3: Wailea Golf Club Emerald Course | D3: =SUM('Golf Log'!$E3:$V3) -> 85 | E3: 4 | F3: 7 | G3: 4 | H3: 4 | I3: 5 | J3: 5 | K3: 4 | L3: 4 | M3: 5 | N3: 4 | O3: 5 | P3: 5 | Q3: 4 | R3: 6 | S3: 6 | T3: 4 | U3: 4 | V3: 5 | W3: 34 | X3: 11 | Y3: 6 | Z3: {=SUMPRODUCT((_xlfn.XLOOKUP(C3, 'Course Stats'!A:A, 'Course Stats'!G:X)=3)*(E3:V3)) / COUNTIF(_xlfn.XLOOKUP(C3, 'Course Stats'!A:A, 'Course Stats'!G:X), 3)} -> 4 | AA3: {=SUMPRODUCT((_xlfn.XLOOKUP(C3, 'Course Stats'!A:A, 'Course Stats'!G:X)=4)*(E3:V3)) / COUNTIF(_xlfn.XLOOKUP(C3, 'Course Stats'!A:A, 'Course Stats'!G:X), 4)} -> 4.7 | AB3: {=SUMPRODUCT((_xlfn.XLOOKUP(C3, 'Course Stats'!A:A, 'Course Stats'!G:X)=5)*(E3:V3)) / COUNTIF(_xlfn.XLOOKUP(C3, 'Course Stats'!A:A, 'Course Stats'!G:X), 5)} -> 5.5
A4: Tyler | B4: 45653 | C4: Wailea Golf Club Gold Course | D4: =SUM('Golf Log'!$E4:$V4) -> 80 | E4: 5 | F4: 6 | G4: 4 | H4: 4 | I4: 4 | J4: 4 | K4: 5 | L4: 3 | M4: 5 | N4: 5 | O4: 3 | P4: 5 | Q4: 5 | R4: 4 | S4: 5 | T4: 4 | U4: 5 | V4: 4 | W4: 31 | X4: 3 | Y4: 5 | Z4: {=SUMPRODUCT((_xlfn.XLOOKUP(C4, 'Course Stats'!A:A, 'Course Stats'!G:X)=3)*(E4:V4)) / COUNTIF(_xlfn.XLOOKUP(C4, 'Course Stats'!A:A, 'Course Stats'!G:X), 3)} -> 3.5 | AA4: {=SUMPRODUCT((_xlfn.XLOOKUP(C4, 'Course Stats'!A:A, 'Course Stats'!G:X)=4)*(E4:V4)) / COUNTIF(_xlfn.XLOOKUP(C4, 'Course Stats'!A:A, 'Course Stats'!G:X), 4)} -> 4.5 | AB4: {=SUMPRODUCT((_xlfn.XLOOKUP(C4, 'Course Stats'!A:A, 'Course Stats'!G:X)=5)*(E4:V4)) / COUNTIF(_xlfn.XLOOKUP(C4, 'Course Stats'!A:A, 'Course Stats'!G:X), 5)} -> 5.25
A5: Tyler | B5: 45649 | C5: Ka'anapali Golf Resort Royal Course | D5: =SUM('Golf Log'!$E5:$V5) -> 88 | E5: 6 | F5: 5 | G5: 5 | H5: 6 | I5: 5 | J5: 5 | K5: 5 | L5: 4 | M5: 6 | N5: 4 | O5: 5 | P5: 5 | Q5: 4 | R5: 5 | S5: 4 | T5: 5 | U5: 4 | V5: 5 | W5: 35 | X5: 5 | Y5: 1 | Z5: {=SUMPRODUCT((_xlfn.XLOOKUP(C5, 'Course Stats'!A:A, 'Course Stats'!G:X)=3)*(E5:V5)) / COUNTIF(_xlfn.XLOOKUP(C5, 'Course Stats'!A:A, 'Course Stats'!G:X), 3)} -> 4.25 | AA5: {=SUMPRODUCT((_xlfn.XLOOKUP(C5, 'Course Stats'!A:A, 'Course Stats'!G:X)=4)*(E5:V5)) / COUNTIF(_xlfn.XLOOKUP(C5, 'Course Stats'!A:A, 'Course Stats'!G:X), 4)} -> 4.9090909 | AB5: {=SUMPRODUCT((_xlfn.XLOOKUP(C5, 'Course Stats'!A:A, 'Course Stats'!G:X)=5)*(E5:V5)) / COUNTIF(_xlfn.XLOOKUP(C5, 'Course Stats'!A:A, 'Course Stats'!G:X), 5)} -> 5.6666667
A6: Tyler | B6: 45580 | C6: Sebonack Golf Club | D6: =SUM('Golf Log'!$E6:$V6) -> 83 | E6: 6 | F6: 6 | G6: 3 | H6: 5 | I6: 3 | J6: 4 | K6: 4 | L6: 3 | M6: 5 | N6: 4 | O6: 5 | P6: 5 | Q6: 6 | R6: 6 | S6: 5 | T6: 5 | U6: 3 | V6: 5 | W6: 29 | X6: 6 | Y6: 5 | Z6: {=SUMPRODUCT((_xlfn.XLOOKUP(C6, 'Course Stats'!A:A, 'Course Stats'!G:X)=3)*(E6:V6)) / COUNTIF(_xlfn.XLOOKUP(C6, 'Course Stats'!A:A, 'Course Stats'!G:X), 3)} -> 4 | AA6: {=SUMPRODUCT((_xlfn.XLOOKUP(C6, 'Course Stats'!A:A, 'Course Stats'!G:X)=4)*(E6:V6)) / COUNTIF(_xlfn.XLOOKUP(C6, 'Course Stats'!A:A, 'Course Stats'!G:X), 4)} -> 4.6 | AB6: {=SUMPRODUCT((_xlfn.XLOOKUP(C6, 'Course Stats'!A:A, 'Course Stats'!G:X)=5)*(E6:V6)) / COUNTIF(_xlfn.XLOOKUP(C6, 'Course Stats'!A:A, 'Course Stats'!G:X), 5)} -> 5.25
A7: Tyler | B7: 45570 | C7: Bethpage Green | D7: =SUM('Golf Log'!$E7:$V7) -> 79 | E7: 4 | F7: 5 | G7: 3 | H7: 4 | I7: 5 | J7: 4 | K7: 5 | L7: 4 | M7: 4 | N7: 4 | O7: 3 | P7: 4 | Q7: 6 | R7: 6 | S7: 4 | T7: 5 | U7: 5 | V7: 4 | W7: 29 | X7: 5 | Y7: 5 | Z7: {=SUMPRODUCT((_xlfn.XLOOKUP(C7, 'Course Stats'!A:A, 'Course Stats'!G:X)=3)*(E7:V7)) / COUNTIF(_xlfn.XLOOKUP(C7, 'Course Stats'!A:A, 'Course Stats'!G:X), 3)} -> 3.5 | AA7: {=SUMPRODUCT((_xlfn.XLOOKUP(C7, 'Course Stats'!A:A, 'Course Stats'!G:X)=4)*(E7:V7)) / COUNTIF(_xlfn.XLOOKUP(C7, 'Course Stats'!A:A, 'Course Stats'!G:X), 4)} -> 4.5454545 | AB7: {=SUMPRODUCT((_xlfn.XLOOKUP(C7, 'Course Stats'!A:A, 'Course Stats'!G:X)=5)*(E7:V7)) / COUNTIF(_xlfn.XLOOKUP(C7, 'Course Stats'!A:A, 'Course Stats'!G:X), 5)} -> 5
A8: Tyler | B8: 45535 | C8: Bethpage Yellow | D8: =SUM('Golf Log'!$E8:$V8) -> 87 | E8: 6 | F8: 5 | G8: 5 | H8: 4 | I8: 5 | J8: 6 | K8: 4 | L8: 5 | M8: 5 | N8: 5 | O8: 5 | P8: 4 | Q8: 5 | R8: 4 | S8: 4 | T8: 5 | U8: 6 | V8: 4 | W8: 32 | X8: 6 | Y8: 3 | Z8: {=SUMPRODUCT((_xlfn.XLOOKUP(C8, 'Course Stats'!A:A, 'Course Stats'!G:X)=3)*(E8:V8)) / COUNTIF(_xlfn.XLOOKUP(C8, 'Course Stats'!A:A, 'Course Stats'!G:X), 3)} -> 4.25 | AA8: {=SUMPRODUCT((_xlfn.XLOOKUP(C8, 'Course Stats'!A:A, 'Course Stats'!G:X)=4)*(E8:V8)) / COUNTIF(_xlfn.XLOOKUP(C8, 'Course Stats'!A:A, 'Course Stats'!G:X), 4)} -> 4.8181818 | AB8: {=SUMPRODUCT((_xlfn.XLOOKUP(C8, 'Course Stats'!A:A, 'Course Stats'!G:X)=5)*(E8:V8)) / COUNTIF(_xlfn.XLOOKUP(C8, 'Course Stats'!A:A, 'Course Stats'!G:X), 5)} -> 5.6666667
A9: Tyler | B9: 45514 | C9: Brentwood Country Club | D9: =SUM('Golf Log'!$E9:$V9) -> 85 | E9: 7 | F9: 5 | G9: 5 | H9: 6 | I9: 3 | J9: 5 | K9: 5 | L9: 5 | M9: 4 | N9: 4 | O9: 4 | P9: 5 | Q9: 5 | R9: 4 | S9: 5 | T9: 4 | U9: 5 | V9: 4 | W9: 31 | X9: 6 | Y9: 4 | Z9: {=SUMPRODUCT((_xlfn.XLOOKUP(C9, 'Course Stats'!A:A, 'Course Stats'!G:X)=3)*(E9:V9)) / COUNTIF(_xlfn.XLOOKUP(C9, 'Course Stats'!A:A, 'Course Stats'!G:X), 3)} -> 4 | AA9: {=SUMPRODUCT((_xlfn.XLOOKUP(C9, 'Course Stats'!A:A, 'Course Stats'!G:X)=4)*(E9:V9)) / COUNTIF(_xlfn.XLOOKUP(C9, 'Course Stats'!A:A, 'Course Stats'!G:X), 4)} -> 4.5833333 | AB9: {=SUMPRODUCT((_xlfn.XLOOKUP(C9, 'Course Stats'!A:A, 'Course Stats'!G:X)=5)*(E9:V9)) / COUNTIF(_xlfn.XLOOKUP(C9, 'Course Stats'!A:A, 'Course Stats'!G:X), 5)} -> 6
A10: Tyler | B10: 45502 | C10: Bethpage Green | D10: =SUM('Golf Log'!$E10:$V10) -> 83 | E10: 4 | F10: 4 | G10: 4 | H10: 4 | I10: 5 | J10: 4 | K10: 5 | L10: 5 | M10: 6 | N10: 4 | O10: 4 | P10: 4 | Q10: 6 | R10: 4 | S10: 4 | T10: 4 | U10: 6 | V10: 6 | W10: 29 | X10: 6 | Y10: 4 | Z10: {=SUMPRODUCT((_xlfn.XLOOKUP(C10, 'Course Stats'!A:A, 'Course Stats'!G:X)=3)*(E10:V10)) / COUNTIF(_xlfn.XLOOKUP(C10, 'Course Stats'!A:A, 'Course Stats'!G:X), 3)} -> 4 | AA10: {=SUMPRODUCT((_xlfn.XLOOKUP(C10, 'Course Stats'!A:A, 'Course Stats'!G:X)=4)*(E10:V10)) / COUNTIF(_xlfn.XLOOKUP(C10, 'Course Stats'!A:A, 'Course Stats'!G:X), 4)} -> 4.5454545 | AB10: {=SUMPRODUCT((_xlfn.XLOOKUP(C10, 'Course Stats'!A:A, 'Course Stats'!G:X)=5)*(E10:V10)) / COUNTIF(_xlfn.XLOOKUP(C10, 'Course Stats'!A:A, 'Course Stats'!G:X), 5)} -> 5.6666667
A11: Tyler | B11: 45496 | C11: Brentwood Country Club | D11: =SUM('Golf Log'!$E11:$V11) -> 79 | E11: 6 | F11: 4 | G11: 4 | H11: 3 | I11: 4 | J11: 5 | K11: 5 | L11: 5 | M11: 4 | N11: 5 | O11: 4 | P11: 5 | Q11: 3 | R11: 4 | S11: 5 | T11: 4 | U11: 4 | V11: 5 | W11: 27 | X11: 9 | Y11: 3 | Z11: {=SUMPRODUCT((_xlfn.XLOOKUP(C11, 'Course Stats'!A:A, 'Course Stats'!G:X)=3)*(E11:V11)) / COUNTIF(_xlfn.XLOOKUP(C11, 'Course Stats'!A:A, 'Course Stats'!G:X), 3)} -> 4 | AA11: {=SUMPRODUCT((_xlfn.XLOOKUP(C11, 'Course Stats'!A:A, 'Course Stats'!G:X)=4)*(E11:V11)) / COUNTIF(_xlfn.XLOOKUP(C11, 'Course Stats'!A:A, 'Course Stats'!G:X), 4)} -> 4.5 | AB11: {=SUMPRODUCT((_xlfn.XLOOKUP(C11, 'Course Stats'!A:A, 'Course Stats'!G:X)=5)*(E11:V11)) / COUNTIF(_xlfn.XLOOKUP(C11, 'Course Stats'!A:A, 'Course Stats'!G:X), 5)} -> 4.3333333
A12: Tyler | B12: 45492 | C12: Brentwood Country Club | D12: =SUM('Golf Log'!$E12:$V12) -> 83 | E12: 6 | F12: 4 | G12: 5 | H12: 5 | I12: 3 | J12: 6 | K12: 4 | L12: 4 | M12: 5 | N12: 4 | O12: 6 | P12: 5 | Q12: 4 | R12: 3 | S12: 5 | T12: 4 | U12: 4 | V12: 6 | W12: 29 | X12: 8 | Y12: 5 | Z12: {=SUMPRODUCT((_xlfn.XLOOKUP(C12, 'Course Stats'!A:A, 'Course Stats'!G:X)=3)*(E12:V12)) / COUNTIF(_xlfn.XLOOKUP(C12, 'Course Stats'!A:A, 'Course Stats'!G:X), 3)} -> 3.6666667 | AA12: {=SUMPRODUCT((_xlfn.XLOOKUP(C12, 'Course Stats'!A:A, 'Course Stats'!G:X)=4)*(E12:V12)) / COUNTIF(_xlfn.XLOOKUP(C12, 'Course Stats'!A:A, 'Course Stats'!G:X), 4)} -> 4.75 | AB12: {=SUMPRODUCT((_xlfn.XLOOKUP(C12, 'Course Stats'!A:A, 'Course Stats'!G:X)=5)*(E12:V12)) / COUNTIF(_xlfn.XLOOKUP(C12, 'Course Stats'!A:A, 'Course Stats'!G:X), 5)} -> 5
A13: Tyler | B13: 45487 | C13: Bethpage Green | D13: =SUM('Golf Log'!$E13:$V13) -> 78 | E13: 4 | F13: 5 | G13: 3 | H13: 4 | I13: 4 | J13: 4 | K13: 5 | L13: 5 | M13: 5 | N13: 5 | O13: 4 | P13: 4 | Q13: 5 | R13: 4 | S13: 4 | T13: 3 | U13: 5 | V13: 5 | W13: 29 | X13: 3 | Y13: 6 | Z13: {=SUMPRODUCT((_xlfn.XLOOKUP(C13, 'Course Stats'!A:A, 'Course Stats'!G:X)=3)*(E13:V13)) / COUNTIF(_xlfn.XLOOKUP(C13, 'Course Stats'!A:A, 'Course Stats'!G:X), 3)} -> 3.75 | AA13: {=SUMPRODUCT((_xlfn.XLOOKUP(C13, 'Course Stats'!A:A, 'Course Stats'!G:X)=4)*(E13:V13)) / COUNTIF(_xlfn.XLOOKUP(C13, 'Course Stats'!A:A, 'Course Stats'!G:X), 4)} -> 4.3636364 | AB13: {=SUMPRODUCT((_xlfn.XLOOKUP(C13, 'Course Stats'!A:A, 'Course Stats'!G:X)=5)*(E13:V13)) / COUNTIF(_xlfn.XLOOKUP(C13, 'Course Stats'!A:A, 'Course Stats'!G:X), 5)} -> 5
... A49: Ryan | B49: 45453 | C49: Willow Creek Hamlet Course | D49: =SUM('Golf Log'!$E49:$V49) -> 109 | E49: 5 | F49: 4 | G49: 7 | H49: 5 | I49: 6 | J49: 7 | K49: 5 | L49: 7 | M49: 8 | N49: 7 | O49: 5 | P49: 7 | Q49: 6 | R49: 6 | S49: 8 | T49: 5 | U49: 5 | V49: 6 | W49: 35 | X49: 0 | Y49: 1 | Z49: {=SUMPRODUCT((_xlfn.XLOOKUP(C49, 'Course Stats'!A:A, 'Course Stats'!G:X)=3)*(E49:V49)) / COUNTIF(_xlfn.XLOOKUP(C49, 'Course Stats'!A:A, 'Course Stats'!G:X), 3)} -> 5 | AA49: {=SUMPRODUCT((_xlfn.XLOOKUP(C49, 'Course Stats'!A:A, 'Course Stats'!G:X)=4)*(E49:V49)) / COUNTIF(_xlfn.XLOOKUP(C49, 'Course Stats'!A:A, 'Course Stats'!G:X), 4)} -> 6.2222222 | AB49: {=SUMPRODUCT((_xlfn.XLOOKUP(C49, 'Course Stats'!A:A, 'Course Stats'!G:X)=5)*(E49:V49)) / COUNTIF(_xlfn.XLOOKUP(C49, 'Course Stats'!A:A, 'Course Stats'!G:X), 5)} -> 7
A50: Rich | B50: 45156 | C50: Middle Island Country Club - Oak and Spruce | D50: =SUM('Golf Log'!$E50:$V50) -> 89 | E50: 5 | F50: 6 | G50: 5 | H50: 4 | I50: 4 | J50: 5 | K50: 5 | L50: 3 | M50: 6 | N50: 6 | O50: 5 | P50: 7 | Q50: 3 | R50: 5 | S50: 5 | T50: 5 | U50: 4 | V50: 6 | Z50: {=SUMPRODUCT((_xlfn.XLOOKUP(C50, 'Course Stats'!A:A, 'Course Stats'!G:X)=3)*(E50:V50)) / COUNTIF(_xlfn.XLOOKUP(C50, 'Course Stats'!A:A, 'Course Stats'!G:X), 3)} -> 3.5 | AA50: {=SUMPRODUCT((_xlfn.XLOOKUP(C50, 'Course Stats'!A:A, 'Course Stats'!G:X)=4)*(E50:V50)) / COUNTIF(_xlfn.XLOOKUP(C50, 'Course Stats'!A:A, 'Course Stats'!G:X), 4)} -> 5.1818182 | AB50: {=SUMPRODUCT((_xlfn.XLOOKUP(C50, 'Course Stats'!A:A, 'Course Stats'!G:X)=5)*(E50:V50)) / COUNTIF(_xlfn.XLOOKUP(C50, 'Course Stats'!A:A, 'Course Stats'!G:X), 5)} -> 6
A51: Rich | B51: 45465 | C51: Wind Watch Hamlet Course | D51: =SUM('Golf Log'!$E51:$V51) -> 99 | E51: 7 | F51: 5 | G51: 5 | H51: 6 | I51: 6 | J51: 4 | K51: 5 | L51: 4 | M51: 6 | N51: 8 | O51: 5 | P51: 5 | Q51: 5 | R51: 5 | S51: 6 | T51: 5 | U51: 6 | V51: 6 | W51: 34 | X51: 0 | Y51: 1 | Z51: {=SUMPRODUCT((_xlfn.XLOOKUP(C51, 'Course Stats'!A:A, 'Course Stats'!G:X)=3)*(E51:V51)) / COUNTIF(_xlfn.XLOOKUP(C51, 'Course Stats'!A:A, 'Course Stats'!G:X), 3)} -> 4.5 | AA51: {=SUMPRODUCT((_xlfn.XLOOKUP(C51, 'Course Stats'!A:A, 'Course Stats'!G:X)=4)*(E51:V51)) / COUNTIF(_xlfn.XLOOKUP(C51, 'Course Stats'!A:A, 'Course Stats'!G:X), 4)} -> 5.6 | AB51: {=SUMPRODUCT((_xlfn.XLOOKUP(C51, 'Course Stats'!A:A, 'Course Stats'!G:X)=5)*(E51:V51)) / COUNTIF(_xlfn.XLOOKUP(C51, 'Course Stats'!A:A, 'Course Stats'!G:X), 5)} -> 6.25
A52: Rich | B52: 45514 | C52: Brentwood Country Club | D52: =SUM('Golf Log'!$E52:$V52) -> 90 | E52: 6 | F52: 5 | G52: 5 | H52: 6 | I52: 4 | J52: 5 | K52: 4 | L52: 4 | M52: 5 | N52: 6 | O52: 6 | P52: 6 | Q52: 5 | R52: 3 | S52: 5 | T52: 5 | U52: 5 | V52: 5 | W52: 28 | X52: 4 | Y52: 1 | Z52: {=SUMPRODUCT((_xlfn.XLOOKUP(C52, 'Course Stats'!A:A, 'Course Stats'!G:X)=3)*(E52:V52)) / COUNTIF(_xlfn.XLOOKUP(C52, 'Course Stats'!A:A, 'Course Stats'!G:X), 3)} -> 4 | AA52: {=SUMPRODUCT((_xlfn.XLOOKUP(C52, 'Course Stats'!A:A, 'Course Stats'!G:X)=4)*(E52:V52)) / COUNTIF(_xlfn.XLOOKUP(C52, 'Course Stats'!A:A, 'Course Stats'!G:X), 4)} -> 5.0833333 | AB52: {=SUMPRODUCT((_xlfn.XLOOKUP(C52, 'Course Stats'!A:A, 'Course Stats'!G:X)=5)*(E52:V52)) / COUNTIF(_xlfn.XLOOKUP(C52, 'Course Stats'!A:A, 'Course Stats'!G:X), 5)} -> 5.6666667
A53: Rich | B53: 45892 | C53: Spring Lake Thunderbird | D53: =SUM('Golf Log'!$E53:$V53) -> 90 | E53: 7 | F53: 4 | G53: 5 | H53: 6 | I53: 4 | J53: 3 | K53: 5 | L53: 5 | M53: 5 | N53: 6 | O53: 6 | P53: 5 | Q53: 3 | R53: 6 | S53: 6 | T53: 4 | U53: 4 | V53: 6 | W53: 38 | X53: 8 | Y53: 6 | Z53: {=SUMPRODUCT((_xlfn.XLOOKUP(C53, 'Course Stats'!A:A, 'Course Stats'!G:X)=3)*(E53:V53)) / COUNTIF(_xlfn.XLOOKUP(C53, 'Course Stats'!A:A, 'Course Stats'!G:X), 3)} -> 3.75 | AA53: {=SUMPRODUCT((_xlfn.XLOOKUP(C53, 'Course Stats'!A:A, 'Course Stats'!G:X)=4)*(E53:V53)) / COUNTIF(_xlfn.XLOOKUP(C53, 'Course Stats'!A:A, 'Course Stats'!G:X), 4)} -> 5.2 | AB53: {=SUMPRODUCT((_xlfn.XLOOKUP(C53, 'Course Stats'!A:A, 'Course Stats'!G:X)=5)*(E53:V53)) / COUNTIF(_xlfn.XLOOKUP(C53, 'Course Stats'!A:A, 'Course Stats'!G:X), 5)} -> 5.75
A54: Rich | B54: 45886 | C54: Spring Lake Thunderbird | D54: =SUM('Golf Log'!$E54:$V54) -> 89 | E54: 6 | F54: 6 | G54: 4 | H54: 6 | I54: 6 | J54: 3 | K54: 4 | L54: 4 | M54: 6 | N54: 4 | O54: 5 | P54: 5 | Q54: 4 | R54: 4 | S54: 6 | T54: 3 | U54: 7 | V54: 6 | W54: 39 | X54: 8 | Y54: 8 | Z54: {=SUMPRODUCT((_xlfn.XLOOKUP(C54, 'Course Stats'!A:A, 'Course Stats'!G:X)=3)*(E54:V54)) / COUNTIF(_xlfn.XLOOKUP(C54, 'Course Stats'!A:A, 'Course Stats'!G:X), 3)} -> 3.5 | AA54: {=SUMPRODUCT((_xlfn.XLOOKUP(C54, 'Course Stats'!A:A, 'Course Stats'!G:X)=4)*(E54:V54)) / COUNTIF(_xlfn.XLOOKUP(C54, 'Course Stats'!A:A, 'Course Stats'!G:X), 4)} -> 5.2 | AB54: {=SUMPRODUCT((_xlfn.XLOOKUP(C54, 'Course Stats'!A:A, 'Course Stats'!G:X)=5)*(E54:V54)) / COUNTIF(_xlfn.XLOOKUP(C54, 'Course Stats'!A:A, 'Course Stats'!G:X), 5)} -> 5.75
A55: Rich | B55: 45897 | C55: Spring Lake Thunderbird | D55: =SUM('Golf Log'!$E55:$V55) -> 90 | E55: 5 | F55: 5 | G55: 4 | H55: 6 | I55: 5 | J55: 3 | K55: 4 | L55: 5 | M55: 6 | N55: 5 | O55: 7 | P55: 5 | Q55: 4 | R55: 4 | S55: 6 | T55: 4 | U55: 6 | V55: 6 | W55: 32 | X55: 5 | Y55: 0 | Z55: {=SUMPRODUCT((_xlfn.XLOOKUP(C55, 'Course Stats'!A:A, 'Course Stats'!G:X)=3)*(E55:V55)) / COUNTIF(_xlfn.XLOOKUP(C55, 'Course Stats'!A:A, 'Course Stats'!G:X), 3)} -> 3.75 | AA55: {=SUMPRODUCT((_xlfn.XLOOKUP(C55, 'Course Stats'!A:A, 'Course Stats'!G:X)=4)*(E55:V55)) / COUNTIF(_xlfn.XLOOKUP(C55, 'Course Stats'!A:A, 'Course Stats'!G:X), 4)} -> 5 | AB55: {=SUMPRODUCT((_xlfn.XLOOKUP(C55, 'Course Stats'!A:A, 'Course Stats'!G:X)=5)*(E55:V55)) / COUNTIF(_xlfn.XLOOKUP(C55, 'Course Stats'!A:A, 'Course Stats'!G:X), 5)} -> 6.25
A56: Rich | B56: 45829 | C56: Brentwood Country Club | D56: =SUM('Golf Log'!$E56:$V56) -> 83 | E56: 6 | F56: 5 | G56: 4 | H56: 6 | I56: 4 | J56: 5 | K56: 5 | L56: 6 | M56: 4 | N56: 5 | O56: 4 | P56: 4 | Q56: 4 | R56: 3 | S56: 4 | T56: 4 | U56: 5 | V56: 5 | W56: 34 | X56: 1 | Y56: 6 | Z56: {=SUMPRODUCT((_xlfn.XLOOKUP(C56, 'Course Stats'!A:A, 'Course Stats'!G:X)=3)*(E56:V56)) / COUNTIF(_xlfn.XLOOKUP(C56, 'Course Stats'!A:A, 'Course Stats'!G:X), 3)} -> 3.6666667 | AA56: {=SUMPRODUCT((_xlfn.XLOOKUP(C56, 'Course Stats'!A:A, 'Course Stats'!G:X)=4)*(E56:V56)) / COUNTIF(_xlfn.XLOOKUP(C56, 'Course Stats'!A:A, 'Course Stats'!G:X), 4)} -> 4.5833333 | AB56: {=SUMPRODUCT((_xlfn.XLOOKUP(C56, 'Course Stats'!A:A, 'Course Stats'!G:X)=5)*(E56:V56)) / COUNTIF(_xlfn.XLOOKUP(C56, 'Course Stats'!A:A, 'Course Stats'!G:X), 5)} -> 5.6666667
A57: Rich | B57: 45857 | C57: Bethpage Green | D57: =SUM('Golf Log'!$E57:$V57) -> 84 | E57: 4 | F57: 6 | G57: 5 | H57: 5 | I57: 5 | J57: 4 | K57: 5 | L57: 3 | M57: 6 | N57: 5 | O57: 5 | P57: 4 | Q57: 5 | R57: 4 | S57: 4 | T57: 4 | U57: 6 | V57: 4 | W57: 35 | X57: 6 | Y57: 8 | Z57: {=SUMPRODUCT((_xlfn.XLOOKUP(C57, 'Course Stats'!A:A, 'Course Stats'!G:X)=3)*(E57:V57)) / COUNTIF(_xlfn.XLOOKUP(C57, 'Course Stats'!A:A, 'Course Stats'!G:X), 3)} -> 4.5 | AA57: {=SUMPRODUCT((_xlfn.XLOOKUP(C57, 'Course Stats'!A:A, 'Course Stats'!G:X)=4)*(E57:V57)) / COUNTIF(_xlfn.XLOOKUP(C57, 'Course Stats'!A:A, 'Course Stats'!G:X), 4)} -> 4.5454545 | AB57: {=SUMPRODUCT((_xlfn.XLOOKUP(C57, 'Course Stats'!A:A, 'Course Stats'!G:X)=5)*(E57:V57)) / COUNTIF(_xlfn.XLOOKUP(C57, 'Course Stats'!A:A, 'Course Stats'!G:X), 5)} -> 5.3333333
A58: Rich | B58: 45844 | C58: Bethpage Green | D58: =SUM('Golf Log'!$E58:$V58) -> 86 | E58: 4 | F58: 6 | G58: 4 | H58: 6 | I58: 4 | J58: 3 | K58: 6 | L58: 4 | M58: 7 | N58: 4 | O58: 4 | P58: 5 | Q58: 6 | R58: 5 | S58: 4 | T58: 5 | U58: 5 | V58: 4 | W58: 31 | X58: 6 | Y58: 3 | Z58: {=SUMPRODUCT((_xlfn.XLOOKUP(C58, 'Course Stats'!A:A, 'Course Stats'!G:X)=3)*(E58:V58)) / COUNTIF(_xlfn.XLOOKUP(C58, 'Course Stats'!A:A, 'Course Stats'!G:X), 3)} -> 3.75 | AA58: {=SUMPRODUCT((_xlfn.XLOOKUP(C58, 'Course Stats'!A:A, 'Course Stats'!G:X)=4)*(E58:V58)) / COUNTIF(_xlfn.XLOOKUP(C58, 'Course Stats'!A:A, 'Course Stats'!G:X), 4)} -> 4.7272727 | AB58: {=SUMPRODUCT((_xlfn.XLOOKUP(C58, 'Course Stats'!A:A, 'Course Stats'!G:X)=5)*(E58:V58)) / COUNTIF(_xlfn.XLOOKUP(C58, 'Course Stats'!A:A, 'Course Stats'!G:X), 5)} -> 6.3333333
